/*
*** modified MRPONYCAPTAIN'S .SCHEMATIC TO .JAVA CONVERTING TOOL v2.0 ***
*/

package com.glistre.glistremod.worldgen;

import java.util.Iterator;
import java.util.List;
import java.util.Random;

import com.glistre.glistremod.blocks.TileEntityGlistreChest;
import com.glistre.glistremod.blocks.fluids.ModFluids;
import com.glistre.glistremod.entities.king.EntityTobieKing;
import com.glistre.glistremod.init.BiomeRegistry;
import com.glistre.glistremod.init.BlockRegistry;
import com.glistre.glistremod.init.GlistreEntityRegistry;
import com.glistre.glistremod.init.ItemRegistry;
import com.glistre.glistremod.lib.Defaults;

import net.minecraftforge.fml.common.IWorldGenerator;
import net.minecraft.block.Block;
import net.minecraft.block.BlockLadder;
import net.minecraft.block.state.IBlockState;
import net.minecraft.client.Minecraft;
import net.minecraft.client.renderer.EnumFaceDirection;
import net.minecraft.entity.player.EntityPlayer;
import net.minecraft.init.Blocks;
import net.minecraft.init.Items;
import net.minecraft.inventory.IInventory;
import net.minecraft.item.ItemStack;
import net.minecraft.tileentity.TileEntityChest;
import net.minecraft.util.AxisAlignedBB;
import net.minecraft.util.BlockPos;
import net.minecraft.util.ChatComponentText;
import net.minecraft.util.EnumChatFormatting;
import net.minecraft.util.EnumFacing;
import net.minecraft.util.WeightedRandomChestContent;
import net.minecraft.world.EnumDifficulty;
import net.minecraft.world.World;
import net.minecraft.world.biome.BiomeGenBase;
import net.minecraft.world.chunk.IChunkProvider;
import net.minecraft.world.gen.feature.WorldGenerator;

public class TobyKingTowerGen extends WorldGenerator implements net.minecraftforge.fml.common.IWorldGenerator
{
	public TobyKingTowerGen() { }	
	
//	@Override
//	public void generate(Random random, int chunkX, int chunkZ, World iChunkProvider chunkGenerator, IChunkProvider chunkProvider) { }
	@Override
    public void generate(Random random, int chunkX, int chunkZ, World worldIn, IChunkProvider chunkGenerator, IChunkProvider chunkProvider) {
        switch(worldIn.provider.getDimensionId())
        {
        
        //case -1 = Nether
            case -1: 
            	generateSurface(random, chunkX*16,chunkZ*16, worldIn, chunkGenerator, chunkProvider);
                break;
        //case 0 = Overworld
            case 0:
            	generateSurface(random, chunkX*16,chunkZ*16, worldIn, chunkGenerator, chunkProvider);
            	break;
        //case 1 = End
            case 1:
            	generateSurface(random, chunkX*16,chunkZ*16, worldIn, chunkGenerator, chunkProvider);
            	break;         	
        //default case e.g. Mystcraft ..others
            default:
            	generateSurface(random, chunkX*16,chunkZ*16, worldIn, chunkGenerator, chunkProvider);
            	break;
        }              
    }
//1.8 conversion next method created	
	public void setBlock(int x, int y, int z, Block block, World world) {
		BlockPos pos = new BlockPos(x,y,z);
		Block b1 = world.getBlockState(pos).getBlock();

	      if(world.isAirBlock(pos) || b1.isLeaves(world, pos))
	      {
	//         IBlockState disblockstate = world.getBlockState(pos);
	         world.setBlockState(pos, block.getDefaultState());
	      }
	   
	}
/*	protected static Minecraft mc = Minecraft.getMinecraft();
	/** Get Player Coordinates */
/*	public static int GetXCoordinate()
	{
		return (int) Math.floor(mc.thePlayer.posX);
	}
	public static int GetYCoordinate()
	{
		return (int) Math.floor(mc.thePlayer.posY);
	}
	public static int GetZCoordinate()
	{
		return (int) Math.floor(mc.thePlayer.posZ);
	}	*/

//1.8 need to fix this method	from 1.7.10
/*	public void setBlockState(BlockPos pos, IBlockState state)
	{
		Block b1 = world.getBlockState(pos);

		if(b1.isAir(world, pos) || b1.isLeaves(world, x, y, z))
		{
			world.setBlock(pos, block, metadata, 2);
		}
	}*/
/*    TobyKingTowerGen tower = new TobyKingTowerGen();
    int chance = rand.nextInt(500);
    for(int i = 0; i < 1; i++)
    {
    int x = chunkX + rand.nextInt(16);
    int z = chunkZ + rand.nextInt(16);
    int chunkY = world.getHeightValue(chunkX, chunkZ);
    if(chance < 5)
    {
    tower.generate(world, rand, chunkX, chunkZ, chunkY);
    }*/

@Override
	public boolean generate(World world, Random rand, BlockPos pos) {
/*		int chunkX = GetXCoordinate() / 16;
		int chunkY = GetYCoordinate() / 16;
		int chunkZ = GetZCoordinate() / 16;
		int inChunkX = GetXCoordinate() % 16;
		int inChunkY = GetYCoordinate()  % 16;
		int inChunkZ = GetZCoordinate() % 16;*/
//		String Chunk = ("" + Integer.toString(inChunkX) + " " + Integer.toString(inChunkY) + " " + Integer.toString(inChunkZ) + " in " + Integer.toString(chunkX) + " " + Integer.toString(chunkY) + " " + Integer.toString(chunkZ)); 
//		mc.fontRendererObj.drawString("C: " + Chunk + "", 2, 32, 0xffffff);
		pos =  new BlockPos(pos.getX(), pos.getY(), pos.getZ());
		boolean b = world.getBiomeGenForCoords(pos).biomeName.equals("Freon Biome");
		
	
/*		//&& world.provider.dimensionId == Defaults.DIM_ID.GLISTRE
     	if (b == true){

        for(int m = 0; m < 1; m++)
        {
         int i = pos.getX() + random.nextInt(16);
         int k =  pos.getZ() + random.nextInt(16);
 //       int Ycoord = worldIn.getHeightValue(i, k) -1;
         int Ycoord = (worldIn.getHeight() - 40) + 40; 
		BiomeGenBase b = world.getBiomeGenForCoords(new BlockPos());
	
		pos =  new BlockPos(pos.getX(), pos.getY(), pos.getZ()); 1.8 */
		//&& world.provider.dimensionId == Defaults.DIM_ID.GLISTRE
     	if (b == true)
	
 //    	int i;
 //    	int j;
//     	int k;
     	
        for(int m = 0; m < 1; m++)
        {
        int i2 = pos.getX();
        int k2 = pos.getZ();
        int i =  i2 + rand.nextInt(15);
        int k =  k2 + rand.nextInt(15);
//        int j = (world.getActualHeight() -1) ;
        int j = world.getChunkFromChunkCoords(i, k).getHeight(i & 15, k & 15) - 1;
       // 
  /*      for(int i =0; i<100; i++){ 
    		BiomeGenBase b = world.getBiomeGenForCoords(new BlockPos(chunkX, 0, chunkZ));   		
            int firstBlockXcoord = chunkX + random.nextInt(16);
            int firstBlockZcoord = chunkZ + random.nextInt(16);
            int OreY = random.nextInt(256); 
            int Ycoord = (world.getHeight() - 40) + 40; */
        
        
        
        
        if(world.getBlockState(pos).getBlock() == Blocks.snow || world.getBlockState(pos).getBlock() == Blocks.ice || world.getBlockState(pos).getBlock() == Blocks.water)
        	//checks if the block at world's height is snow or ice or water
        {
        //	(random.nextFloat < 0.01= would be 1 in 100 ?
     //  if (rand.nextFloat() < .99) 
        	// if((rand.nextInt(2)+1)==1) //this one sets its rarity in here
        	/*"if random.nextInt(number) == 1" 
        	 * where your chance of that chunk having your structure in it would be 1/number. 
        	 * So having number = 1 would be always, number = 2 would be half, etc.*/
        	if((rand.nextInt(10) + 1)== 1) 
        				
        {
/*        boolean place = true;

        for (int y1 = 0; y1<6; y1++) //checks for air on the Y axis as tall as the structure is.
        for (int z1 = 0; z1<5; z1++) //checks for air on the Z axis as wide as the structure is.
        for (int x1 = 0; x1<5; x1++) //checks for air on the X axis as wide as the structure is.
        if(world.getBlockState(i + x1, j + y1 + 1 , k + z1).getBlock() !=Blocks.air) //checks each of the above blocks for air blocks
        place = false; //disallows spawning if all above blocks aren't air
        if(place){*/
        
 //1.8 correct way to set blocks    	world.setBlockState ( new BlockPos(i + 0,j + 0,k + 0), (IBlockState) Blocks.snow.getDefaultState();
//		this.setBlockState(world, pos, Blocks.snow, 0);

		this.setBlock(i + 0, j + 0, k + 2, Blocks.snow, world);
		this.setBlock(i + 0, j + 0, k + 3, Blocks.snow, world);
		this.setBlock(i + 0, j + 0, k + 4, Blocks.snow, world);
		this.setBlock(i + 0, j + 0, k + 5, Blocks.snow, world);
		this.setBlock(i + 0, j + 0, k + 6, Blocks.snow, world);
		this.setBlock(i + 0, j + 0, k + 7, Blocks.snow, world);
		this.setBlock(i + 0, j + 0, k + 8, Blocks.snow, world);
		this.setBlock(i + 0, j + 0, k + 9, Blocks.snow, world);
		this.setBlock(i + 0, j + 0, k + 10, Blocks.snow, world);
		this.setBlock(i + 0, j + 0, k + 11, Blocks.snow, world);
		this.setBlock(i + 0, j + 0, k + 12, Blocks.snow, world);
		this.setBlock(i + 0, j + 0, k + 13, Blocks.snow, world);
		this.setBlock(i + 0, j + 0, k + 14, Blocks.snow, world);
		this.setBlock(i + 0, j + 0, k + 15, Blocks.snow, world);
		this.setBlock(i + 0, j + 0, k + 16, Blocks.snow, world);
		this.setBlock(i + 0, j + 0, k + 17, Blocks.snow, world);
		this.setBlock(i + 0, j + 0, k + 18, Blocks.snow, world);
		this.setBlock(i + 0, j + 0, k + 19, Blocks.snow, world);
		this.setBlock(i + 0, j + 0, k + 20, Blocks.snow, world);
		this.setBlock(i + 0, j + 0, k + 21, Blocks.snow, world);
		this.setBlock(i + 0, j + 0, k + 22, Blocks.snow, world);
		this.setBlock(i + 0, j + 0, k + 23, Blocks.snow, world);
		this.setBlock(i + 0, j + 0, k + 24, Blocks.snow, world);
		this.setBlock(i + 0, j + 0, k + 25, Blocks.snow, world);
		this.setBlock(i + 0, j + 0, k + 26, Blocks.snow, world);
		this.setBlock(i + 0, j + 0, k + 27, Blocks.snow, world);
		this.setBlock(i + 0, j + 0, k + 28, Blocks.snow, world);
		this.setBlock(i + 0, j + 0, k + 29, Blocks.snow, world);
		this.setBlock(i + 0, j + 0, k + 30, Blocks.snow, world);
		this.setBlock(i + 0, j + 0, k + 31, Blocks.snow, world);
		this.setBlock(i + 1, j + 0, k + 0, Blocks.snow, world);
		this.setBlock(i + 1, j + 0, k + 1, Blocks.snow, world);
		this.setBlock(i + 1, j + 0, k + 2, Blocks.snow, world);
		this.setBlock(i + 1, j + 0, k + 3, Blocks.snow, world);
		this.setBlock(i + 1, j + 0, k + 4, Blocks.snow, world);
		this.setBlock(i + 1, j + 0, k + 5, Blocks.snow, world);
		this.setBlock(i + 1, j + 0, k + 6, Blocks.snow, world);
		this.setBlock(i + 1, j + 0, k + 7, Blocks.snow, world);
		this.setBlock(i + 1, j + 0, k + 8, Blocks.snow, world);
		this.setBlock(i + 1, j + 0, k + 9, Blocks.snow, world);
		this.setBlock(i + 1, j + 0, k + 10, Blocks.snow, world);
		this.setBlock(i + 1, j + 0, k + 11, Blocks.snow, world);
		this.setBlock(i + 1, j + 0, k + 12, Blocks.snow, world);
		this.setBlock(i + 1, j + 0, k + 13, Blocks.snow, world);
		this.setBlock(i + 1, j + 0, k + 14, Blocks.snow, world);
		this.setBlock(i + 1, j + 0, k + 15, Blocks.snow, world);
		this.setBlock(i + 1, j + 0, k + 16, Blocks.snow, world);
		this.setBlock(i + 1, j + 0, k + 17, Blocks.snow, world);
		this.setBlock(i + 1, j + 0, k + 18, Blocks.snow, world);
		this.setBlock(i + 1, j + 0, k + 19, Blocks.snow, world);
		this.setBlock(i + 1, j + 0, k + 20, Blocks.snow, world);
		this.setBlock(i + 1, j + 0, k + 21, Blocks.snow, world);
		this.setBlock(i + 1, j + 0, k + 22, Blocks.snow, world);
		this.setBlock(i + 1, j + 0, k + 23, Blocks.snow, world);
		this.setBlock(i + 1, j + 0, k + 24, Blocks.snow, world);
		this.setBlock(i + 1, j + 0, k + 25, Blocks.snow, world);
		this.setBlock(i + 1, j + 0, k + 26, Blocks.snow, world);
		this.setBlock(i + 1, j + 0, k + 27, Blocks.snow, world);
		this.setBlock(i + 1, j + 0, k + 28, Blocks.snow, world);
		this.setBlock(i + 1, j + 0, k + 29, Blocks.snow, world);
		this.setBlock(i + 1, j + 0, k + 30, Blocks.snow, world);
		this.setBlock(i + 1, j + 0, k + 31, Blocks.snow, world);
		this.setBlock(i + 2, j + 0, k + 0, Blocks.snow, world);
		this.setBlock(i + 2, j + 0, k + 1, Blocks.snow, world);
		this.setBlock(i + 2, j + 0, k + 2, Blocks.snow, world);
		this.setBlock(i + 2, j + 0, k + 3, Blocks.snow, world);
		this.setBlock(i + 2, j + 0, k + 4, Blocks.snow, world);
		this.setBlock(i + 2, j + 0, k + 5, Blocks.snow, world);
		this.setBlock(i + 2, j + 0, k + 6, Blocks.snow, world);
		this.setBlock(i + 2, j + 0, k + 7, Blocks.snow, world);
		this.setBlock(i + 2, j + 0, k + 8, Blocks.snow, world);
		this.setBlock(i + 2, j + 0, k + 9, Blocks.snow, world);
		this.setBlock(i + 2, j + 0, k + 10, Blocks.snow, world);
		this.setBlock(i + 2, j + 0, k + 11, Blocks.snow, world);
		this.setBlock(i + 2, j + 0, k + 12, Blocks.snow, world);
		this.setBlock(i + 2, j + 0, k + 13, Blocks.snow, world);
		this.setBlock(i + 2, j + 0, k + 14, Blocks.snow, world);
		this.setBlock(i + 2, j + 0, k + 15, Blocks.snow, world);
		this.setBlock(i + 2, j + 0, k + 16, Blocks.snow, world);
		this.setBlock(i + 2, j + 0, k + 17, Blocks.snow, world);
		this.setBlock(i + 2, j + 0, k + 18, Blocks.snow, world);
		this.setBlock(i + 2, j + 0, k + 19, Blocks.snow, world);
		this.setBlock(i + 2, j + 0, k + 20, Blocks.snow, world);
		this.setBlock(i + 2, j + 0, k + 21, Blocks.snow, world);
		this.setBlock(i + 2, j + 0, k + 22, Blocks.snow, world);
		this.setBlock(i + 2, j + 0, k + 23, Blocks.snow, world);
		this.setBlock(i + 2, j + 0, k + 24, Blocks.snow, world);
		this.setBlock(i + 2, j + 0, k + 25, Blocks.snow, world);
		this.setBlock(i + 2, j + 0, k + 26, Blocks.snow, world);
		this.setBlock(i + 2, j + 0, k + 27, Blocks.snow, world);
		this.setBlock(i + 2, j + 0, k + 28, Blocks.snow, world);
		this.setBlock(i + 2, j + 0, k + 29, Blocks.snow, world);
		this.setBlock(i + 2, j + 0, k + 30, Blocks.snow, world);
		this.setBlock(i + 2, j + 0, k + 31, Blocks.snow, world);
		this.setBlock(i +3, j + 0, k + 0, Blocks.snow, world);
		this.setBlock(i +3, j + 0, k + 1, Blocks.snow, world);
		this.setBlock(i +3, j + 0, k + 2, Blocks.snow, world);
		this.setBlock(i +3, j + 0, k + 3, Blocks.snow, world);
		this.setBlock(i +3, j + 0, k + 4, Blocks.snow, world);
		this.setBlock(i +3, j + 0, k + 5, Blocks.snow, world);
		this.setBlock(i +3, j + 0, k + 6, Blocks.snow, world);
		this.setBlock(i +3, j + 0, k + 7, Blocks.snow, world);
		this.setBlock(i +3, j + 0, k + 8, Blocks.snow, world);
		this.setBlock(i +3, j + 0, k + 9, Blocks.snow, world);
		this.setBlock(i +3, j + 0, k + 10, Blocks.snow, world);
		this.setBlock(i +3, j + 0, k + 11, Blocks.snow, world);
		this.setBlock(i +3, j + 0, k + 12, Blocks.snow, world);
		this.setBlock(i +3, j + 0, k + 13, Blocks.snow, world);
		this.setBlock(i +3, j + 0, k + 14, Blocks.snow, world);
		this.setBlock(i +3, j + 0, k + 15, Blocks.snow, world);
		this.setBlock(i +3, j + 0, k + 16, Blocks.snow, world);
		this.setBlock(i +3, j + 0, k + 17, Blocks.snow, world);
		this.setBlock(i +3, j + 0, k + 18, Blocks.snow, world);
		this.setBlock(i +3, j + 0, k + 19, Blocks.snow, world);
		this.setBlock(i +3, j + 0, k + 20, Blocks.snow, world);
		this.setBlock(i +3, j + 0, k + 21, Blocks.snow, world);
		this.setBlock(i +3, j + 0, k + 22, Blocks.snow, world);
		this.setBlock(i +3, j + 0, k + 23, Blocks.snow, world);
		this.setBlock(i +3, j + 0, k + 24, Blocks.snow, world);
		this.setBlock(i +3, j + 0, k + 25, Blocks.snow, world);
		this.setBlock(i +3, j + 0, k + 26, Blocks.snow, world);
		this.setBlock(i +3, j + 0, k + 27, Blocks.snow, world);
		this.setBlock(i +3, j + 0, k + 28, Blocks.snow, world);
		this.setBlock(i +3, j + 0, k + 29, Blocks.snow, world);
		this.setBlock(i +3, j + 0, k + 30, Blocks.snow, world);
		this.setBlock(i +3, j + 0, k + 31, Blocks.snow, world);
		this.setBlock(i + 4, j + 0, k + 0, Blocks.snow, world);
		this.setBlock(i + 4, j + 0, k + 1, Blocks.snow, world);
		this.setBlock(i + 4, j + 0, k + 2, Blocks.snow, world);
		this.setBlock(i + 4, j + 0, k + 3, Blocks.snow, world);
		this.setBlock(i + 4, j + 0, k + 4, Blocks.snow, world);
		this.setBlock(i + 4, j + 0, k + 5, Blocks.snow, world);
		this.setBlock(i + 4, j + 0, k + 6, Blocks.snow, world);
		this.setBlock(i + 4, j + 0, k + 7, Blocks.snow, world);
		this.setBlock(i + 4, j + 0, k + 8, Blocks.snow, world);
		this.setBlock(i + 4, j + 0, k + 9, Blocks.snow, world);
		this.setBlock(i + 4, j + 0, k + 10, Blocks.snow, world);
		this.setBlock(i + 4, j + 0, k + 11, Blocks.snow, world);
		this.setBlock(i + 4, j + 0, k + 12, Blocks.snow, world);
		this.setBlock(i + 4, j + 0, k + 13, Blocks.snow, world);
		this.setBlock(i + 4, j + 0, k + 14, Blocks.snow, world);
		this.setBlock(i + 4, j + 0, k + 15, Blocks.snow, world);
		this.setBlock(i + 4, j + 0, k + 16, Blocks.snow, world);
		this.setBlock(i + 4, j + 0, k + 17, Blocks.snow, world);
		this.setBlock(i + 4, j + 0, k + 18, Blocks.snow, world);
		this.setBlock(i + 4, j + 0, k + 19, Blocks.snow, world);
		this.setBlock(i + 4, j + 0, k + 20, Blocks.snow, world);
		this.setBlock(i + 4, j + 0, k + 21, Blocks.snow, world);
		this.setBlock(i + 4, j + 0, k + 22, Blocks.snow, world);
		this.setBlock(i + 4, j + 0, k + 23, Blocks.snow, world);
		this.setBlock(i + 4, j + 0, k + 24, Blocks.snow, world);
		this.setBlock(i + 4, j + 0, k + 25, Blocks.snow, world);
		this.setBlock(i + 4, j + 0, k + 26, Blocks.snow, world);
		this.setBlock(i + 4, j + 0, k + 27, Blocks.snow, world);
		this.setBlock(i + 4, j + 0, k + 28, Blocks.snow, world);
		this.setBlock(i + 4, j + 0, k + 29, Blocks.snow, world);
		this.setBlock(i + 4, j + 0, k + 30, Blocks.snow, world);
		this.setBlock(i + 4, j + 0, k + 31, Blocks.snow, world);
		this.setBlock(i + 5, j + 0, k + 0, Blocks.snow, world);
		this.setBlock(i + 5, j + 0, k + 1, Blocks.snow, world);
		this.setBlock(i + 5, j + 0, k + 2, Blocks.snow, world);
		this.setBlock(i + 5, j + 0, k + 3, Blocks.snow, world);
		this.setBlock(i + 5, j + 0, k + 4, Blocks.snow, world);
		this.setBlock(i + 5, j + 0, k + 5, Blocks.snow, world);
		this.setBlock(i + 5, j + 0, k + 6, Blocks.snow, world);
		this.setBlock(i + 5, j + 0, k + 7, Blocks.snow, world);
		this.setBlock(i + 5, j + 0, k + 8, Blocks.snow, world);
		this.setBlock(i + 5, j + 0, k + 9, Blocks.snow, world);
		this.setBlock(i + 5, j + 0, k + 10, Blocks.snow, world);
		this.setBlock(i + 5, j + 0, k + 11, Blocks.snow, world);
		this.setBlock(i + 5, j + 0, k + 12, Blocks.snow, world);
		this.setBlock(i + 5, j + 0, k + 13, Blocks.snow, world);
		this.setBlock(i + 5, j + 0, k + 14, Blocks.snow, world);
		this.setBlock(i + 5, j + 0, k + 15, Blocks.snow, world);
		this.setBlock(i + 5, j + 0, k + 16, Blocks.snow, world);
		this.setBlock(i + 5, j + 0, k + 17, Blocks.snow, world);
		this.setBlock(i + 5, j + 0, k + 18, Blocks.snow, world);
		this.setBlock(i + 5, j + 0, k + 19, Blocks.snow, world);
		this.setBlock(i + 5, j + 0, k + 20, Blocks.snow, world);
		this.setBlock(i + 5, j + 0, k + 21, Blocks.snow, world);
		this.setBlock(i + 5, j + 0, k + 22, Blocks.snow, world);
		this.setBlock(i + 5, j + 0, k + 23, Blocks.snow, world);
		this.setBlock(i + 5, j + 0, k + 24, Blocks.snow, world);
		this.setBlock(i + 5, j + 0, k + 25, Blocks.snow, world);
		this.setBlock(i + 5, j + 0, k + 26, Blocks.snow, world);
		this.setBlock(i + 5, j + 0, k + 27, Blocks.snow, world);
		this.setBlock(i + 5, j + 0, k + 28, Blocks.snow, world);
		this.setBlock(i + 5, j + 0, k + 29, Blocks.snow, world);
		this.setBlock(i + 5, j + 0, k + 30, Blocks.snow, world);
		this.setBlock(i + 5, j + 0, k + 31, Blocks.snow, world);
		this.setBlock(i + 6, j + 0, k + 0, Blocks.snow, world);
		this.setBlock(i + 6, j + 0, k + 1, Blocks.snow, world);
		this.setBlock(i + 6, j + 0, k + 2, Blocks.snow, world);
		this.setBlock(i + 6, j + 0, k + 3, Blocks.snow, world);
		this.setBlock(i + 6, j + 0, k + 4, Blocks.snow, world);
		this.setBlock(i + 6, j + 0, k + 5, Blocks.snow, world);
		this.setBlock(i + 6, j + 0, k + 6, Blocks.snow, world);
		this.setBlock(i + 6, j + 0, k + 7, Blocks.snow, world);
		this.setBlock(i + 6, j + 0, k + 8, Blocks.snow, world);
		this.setBlock(i + 6, j + 0, k + 9, Blocks.snow, world);
		this.setBlock(i + 6, j + 0, k + 10, Blocks.snow, world);
		this.setBlock(i + 6, j + 0, k + 11, Blocks.snow, world);
		this.setBlock(i + 6, j + 0, k + 12, Blocks.snow, world);
		this.setBlock(i + 6, j + 0, k + 13, Blocks.snow, world);
		this.setBlock(i + 6, j + 0, k + 14, Blocks.snow, world);
		this.setBlock(i + 6, j + 0, k + 15, Blocks.snow, world);
		this.setBlock(i + 6, j + 0, k + 16, Blocks.snow, world);
		this.setBlock(i + 6, j + 0, k + 17, Blocks.snow, world);
		this.setBlock(i + 6, j + 0, k + 18, Blocks.snow, world);
		this.setBlock(i + 6, j + 0, k + 19, Blocks.snow, world);
		this.setBlock(i + 6, j + 0, k + 20, Blocks.snow, world);
		this.setBlock(i + 6, j + 0, k + 21, Blocks.snow, world);
		this.setBlock(i + 6, j + 0, k + 22, Blocks.snow, world);
		this.setBlock(i + 6, j + 0, k + 23, Blocks.snow, world);
		this.setBlock(i + 6, j + 0, k + 24, Blocks.snow, world);
		this.setBlock(i + 6, j + 0, k + 25, Blocks.snow, world);
		this.setBlock(i + 6, j + 0, k + 26, Blocks.snow, world);
		this.setBlock(i + 6, j + 0, k + 27, Blocks.snow, world);
		this.setBlock(i + 6, j + 0, k + 28, Blocks.snow, world);
		this.setBlock(i + 6, j + 0, k + 29, Blocks.snow, world);
		this.setBlock(i + 6, j + 0, k + 30, Blocks.snow, world);
		this.setBlock(i + 6, j + 0, k + 31, Blocks.snow, world);
		this.setBlock(i + 7, j + 0, k + 0, Blocks.snow, world);
		this.setBlock(i + 7, j + 0, k + 1, Blocks.snow, world);
		this.setBlock(i + 7, j + 0, k + 2, Blocks.snow, world);
		this.setBlock(i + 7, j + 0, k + 3, Blocks.snow, world);
		this.setBlock(i + 7, j + 0, k + 4, Blocks.snow, world);
		this.setBlock(i + 7, j + 0, k + 5, Blocks.snow, world);
		this.setBlock(i + 7, j + 0, k + 6, Blocks.snow, world);
		this.setBlock(i + 7, j + 0, k + 7, Blocks.snow, world);
		this.setBlock(i + 7, j + 0, k + 8, Blocks.snow, world);
		this.setBlock(i + 7, j + 0, k + 9, Blocks.snow, world);
		this.setBlock(i + 7, j + 0, k + 10, Blocks.snow, world);
		this.setBlock(i + 7, j + 0, k + 11, Blocks.snow, world);
		this.setBlock(i + 7, j + 0, k + 12, Blocks.snow, world);
		this.setBlock(i + 7, j + 0, k + 13, Blocks.snow, world);
		this.setBlock(i + 7, j + 0, k + 14, Blocks.snow, world);
		this.setBlock(i + 7, j + 0, k + 15, Blocks.snow, world);
		this.setBlock(i + 7, j + 0, k + 16, Blocks.snow, world);
		this.setBlock(i + 7, j + 0, k + 17, Blocks.snow, world);
		this.setBlock(i + 7, j + 0, k + 18, Blocks.snow, world);
		this.setBlock(i + 7, j + 0, k + 19, Blocks.snow, world);
		this.setBlock(i + 7, j + 0, k + 20, Blocks.snow, world);
		this.setBlock(i + 7, j + 0, k + 21, Blocks.snow, world);
		this.setBlock(i + 7, j + 0, k + 22, Blocks.snow, world);
		this.setBlock(i + 7, j + 0, k + 23, Blocks.snow, world);
		this.setBlock(i + 7, j + 0, k + 24, Blocks.snow, world);
		this.setBlock(i + 7, j + 0, k + 25, Blocks.snow, world);
		this.setBlock(i + 7, j + 0, k + 26, Blocks.snow, world);
		this.setBlock(i + 7, j + 0, k + 27, Blocks.snow, world);
		this.setBlock(i + 7, j + 0, k + 28, Blocks.snow, world);
		this.setBlock(i + 7, j + 0, k + 29, Blocks.snow, world);
		this.setBlock(i + 7, j + 0, k + 30, Blocks.snow, world);
		this.setBlock(i + 7, j + 0, k + 31, Blocks.snow, world);
		//all silver blocks had a 3 where I replaced with world for 1.8 update
		this.setBlock(i + 7, j + 34, k + 15, BlockRegistry.void_block_1, world);
		this.setBlock(i + 7, j + 34, k + 16, BlockRegistry.void_block_1, world);
		this.setBlock(i +8, j + 0, k + 0, Blocks.snow, world);
		this.setBlock(i +8, j + 0, k + 1, Blocks.snow, world);
		this.setBlock(i +8, j + 0, k + 2, Blocks.snow, world);
		this.setBlock(i +8, j + 0, k + 3, Blocks.snow, world);
		this.setBlock(i +8, j + 0, k + 4, Blocks.snow, world);
		this.setBlock(i +8, j + 0, k + 5, Blocks.snow, world);
		this.setBlock(i +8, j + 0, k + 6, Blocks.snow, world);
		this.setBlock(i +8, j + 0, k + 7, Blocks.snow, world);
		this.setBlock(i +8, j + 0, k + 8, Blocks.snow, world);
		this.setBlock(i +8, j + 0, k + 9, Blocks.snow, world);
		this.setBlock(i +8, j + 0, k + 10, Blocks.snow, world);
		this.setBlock(i +8, j + 0, k + 11, Blocks.snow, world);
		this.setBlock(i +8, j + 0, k + 12, Blocks.snow, world);
		this.setBlock(i +8, j + 0, k + 13, Blocks.snow, world);
		this.setBlock(i +8, j + 0, k + 14, Blocks.snow, world);
		this.setBlock(i +8, j + 0, k + 15, Blocks.snow, world);
		this.setBlock(i +8, j + 0, k + 16, Blocks.snow, world);
		this.setBlock(i +8, j + 0, k + 17, Blocks.snow, world);
		this.setBlock(i +8, j + 0, k + 18, Blocks.snow, world);
		this.setBlock(i +8, j + 0, k + 19, Blocks.snow, world);
		this.setBlock(i +8, j + 0, k + 20, Blocks.snow, world);
		this.setBlock(i +8, j + 0, k + 21, Blocks.snow, world);
		this.setBlock(i +8, j + 0, k + 22, Blocks.snow, world);
		this.setBlock(i +8, j + 0, k + 23, Blocks.snow, world);
		this.setBlock(i +8, j + 0, k + 24, Blocks.snow, world);
		this.setBlock(i +8, j + 0, k + 25, Blocks.snow, world);
		this.setBlock(i +8, j + 0, k + 26, Blocks.snow, world);
		this.setBlock(i +8, j + 0, k + 27, Blocks.snow, world);
		this.setBlock(i +8, j + 0, k + 28, Blocks.snow, world);
		this.setBlock(i +8, j + 0, k + 29, Blocks.snow, world);
		this.setBlock(i +8, j + 0, k + 30, Blocks.snow, world);
		this.setBlock(i +8, j + 0, k + 31, Blocks.snow, world);
		this.setBlock(i +8, j + 34, k + 14, BlockRegistry.void_block_1, world);
		this.setBlock(i +8, j + 34, k + 15, BlockRegistry.void_block_1, world);
		this.setBlock(i +8, j + 34, k + 16, BlockRegistry.void_block_1, world);
		this.setBlock(i +8, j + 34, k + 17, BlockRegistry.void_block_1, world);
		this.setBlock(i + 9, j + 0, k + 0, Blocks.snow, world);
		this.setBlock(i + 9, j + 0, k + 1, Blocks.snow, world);
		this.setBlock(i + 9, j + 0, k + 2, Blocks.snow, world);
		this.setBlock(i + 9, j + 0, k + 3, Blocks.snow, world);
		this.setBlock(i + 9, j + 0, k + 4, Blocks.snow, world);
		this.setBlock(i + 9, j + 0, k + 5, Blocks.snow, world);
		this.setBlock(i + 9, j + 0, k + 6, Blocks.snow, world);
		this.setBlock(i + 9, j + 0, k + 7, Blocks.snow, world);
		this.setBlock(i + 9, j + 0, k + 8, Blocks.snow, world);
		this.setBlock(i + 9, j + 0, k + 9, Blocks.snow, world);
		this.setBlock(i + 9, j + 0, k + 10, Blocks.snow, world);
		this.setBlock(i + 9, j + 0, k + 11, Blocks.snow, world);
		this.setBlock(i + 9, j + 0, k + 12, Blocks.snow, world);
		this.setBlock(i + 9, j + 0, k + 13, Blocks.snow, world);
		this.setBlock(i + 9, j + 0, k + 14, Blocks.snow, world);
		this.setBlock(i + 9, j + 0, k + 15, Blocks.snow, world);
		this.setBlock(i + 9, j + 0, k + 16, Blocks.snow, world);
		this.setBlock(i + 9, j + 0, k + 17, Blocks.snow, world);
		this.setBlock(i + 9, j + 0, k + 18, Blocks.snow, world);
		this.setBlock(i + 9, j + 0, k + 19, Blocks.snow, world);
		this.setBlock(i + 9, j + 0, k + 20, Blocks.snow, world);
		this.setBlock(i + 9, j + 0, k + 21, Blocks.snow, world);
		this.setBlock(i + 9, j + 0, k + 22, Blocks.snow, world);
		this.setBlock(i + 9, j + 0, k + 23, Blocks.snow, world);
		this.setBlock(i + 9, j + 0, k + 24, Blocks.snow, world);
		this.setBlock(i + 9, j + 0, k + 25, Blocks.snow, world);
		this.setBlock(i + 9, j + 0, k + 26, Blocks.snow, world);
		this.setBlock(i + 9, j + 0, k + 27, Blocks.snow, world);
		this.setBlock(i + 9, j + 0, k + 28, Blocks.snow, world);
		this.setBlock(i + 9, j + 0, k + 29, Blocks.snow, world);
		this.setBlock(i + 9, j + 0, k + 30, Blocks.snow, world);
		this.setBlock(i + 9, j + 0, k + 31, Blocks.snow, world);
		this.setBlock(i + 9, j + 34, k + 13, BlockRegistry.void_block_1, world);
		this.setBlock(i + 9, j + 34, k + 14, BlockRegistry.void_block_1, world);
		this.setBlock(i + 9, j + 34, k + 15, BlockRegistry.silver_ore_1, world);
		this.setBlock(i + 9, j + 34, k + 16, BlockRegistry.silver_ore_1, world);
		this.setBlock(i + 9, j + 34, k + 17, BlockRegistry.void_block_1, world);
		this.setBlock(i + 9, j + 34, k + 18, BlockRegistry.void_block_1, world);
		this.setBlock(i + 10, j + 0, k + 0, Blocks.snow, world);
		this.setBlock(i + 10, j + 0, k + 1, Blocks.snow, world);
		this.setBlock(i + 10, j + 0, k + 2, Blocks.snow, world);
		this.setBlock(i + 10, j + 0, k + 3, Blocks.snow, world);
		this.setBlock(i + 10, j + 0, k + 4, Blocks.snow, world);
		this.setBlock(i + 10, j + 0, k + 5, Blocks.snow, world);
		this.setBlock(i + 10, j + 0, k + 6, Blocks.snow, world);
		this.setBlock(i + 10, j + 0, k + 7, Blocks.snow, world);
		this.setBlock(i + 10, j + 0, k + 8, Blocks.snow, world);
		this.setBlock(i + 10, j + 0, k + 9, Blocks.snow, world);
		this.setBlock(i + 10, j + 0, k + 10, Blocks.snow, world);
		this.setBlock(i + 10, j + 0, k + 11, Blocks.snow, world);
		this.setBlock(i + 10, j + 0, k + 12, Blocks.snow, world);
		this.setBlock(i + 10, j + 0, k + 13, Blocks.snow, world);
		this.setBlock(i + 10, j + 0, k + 14, Blocks.snow, world);
		this.setBlock(i + 10, j + 0, k + 15, Blocks.snow, world);
		this.setBlock(i + 10, j + 0, k + 16, Blocks.snow, world);
		this.setBlock(i + 10, j + 0, k + 17, Blocks.snow, world);
		this.setBlock(i + 10, j + 0, k + 18, Blocks.snow, world);
		this.setBlock(i + 10, j + 0, k + 19, Blocks.snow, world);
		this.setBlock(i + 10, j + 0, k + 20, Blocks.snow, world);
		this.setBlock(i + 10, j + 0, k + 21, Blocks.snow, world);
		this.setBlock(i + 10, j + 0, k + 22, Blocks.snow, world);
		this.setBlock(i + 10, j + 0, k + 23, Blocks.snow, world);
		this.setBlock(i + 10, j + 0, k + 24, Blocks.snow, world);
		this.setBlock(i + 10, j + 0, k + 25, Blocks.snow, world);
		this.setBlock(i + 10, j + 0, k + 26, Blocks.snow, world);
		this.setBlock(i + 10, j + 0, k + 27, Blocks.snow, world);
		this.setBlock(i + 10, j + 0, k + 28, Blocks.snow, world);
		this.setBlock(i + 10, j + 0, k + 29, Blocks.snow, world);
		this.setBlock(i + 10, j + 0, k + 30, Blocks.snow, world);
		this.setBlock(i + 10, j + 0, k + 31, Blocks.snow, world);
		this.setBlock(i + 10, j + 33, k + 13, BlockRegistry.void_block_1, world);
		this.setBlock(i + 10, j + 33, k + 14, BlockRegistry.silver_ore_1, world);
		this.setBlock(i + 10, j + 33, k + 15, BlockRegistry.void_block_1, world);
		this.setBlock(i + 10, j + 33, k + 16, BlockRegistry.void_block_1, world);
		this.setBlock(i + 10, j + 33, k + 17, BlockRegistry.silver_ore_1, world);
		this.setBlock(i + 10, j + 33, k + 18, BlockRegistry.void_block_1, world);
		this.setBlock(i + 10, j + 34, k + 12, BlockRegistry.void_block_1, world);
		this.setBlock(i + 10, j + 34, k + 13, BlockRegistry.silver_ore_1, world);
		this.setBlock(i + 10, j + 34, k + 14, BlockRegistry.void_block_1, world);
		this.setBlock(i + 10, j + 34, k + 15, BlockRegistry.void_block_1, world);
		this.setBlock(i + 10, j + 34, k + 16, BlockRegistry.void_block_1, world);
		this.setBlock(i + 10, j + 34, k + 17, BlockRegistry.void_block_1, world);
		this.setBlock(i + 10, j + 34, k + 18, BlockRegistry.silver_ore_1, world);
		this.setBlock(i + 10, j + 34, k + 19, BlockRegistry.void_block_1, world);
		this.setBlock(i + 11, j + 0, k + 0, Blocks.snow, world);
		this.setBlock(i + 11, j + 0, k + 1, Blocks.snow, world);
		this.setBlock(i + 11, j + 0, k + 2, Blocks.snow, world);
		this.setBlock(i + 11, j + 0, k + 3, Blocks.snow, world);
		this.setBlock(i + 11, j + 0, k + 4, Blocks.snow, world);
		this.setBlock(i + 11, j + 0, k + 5, Blocks.snow, world);
		this.setBlock(i + 11, j + 0, k + 6, Blocks.snow, world);
		this.setBlock(i + 11, j + 0, k + 7, Blocks.snow, world);
		this.setBlock(i + 11, j + 0, k + 8, Blocks.snow, world);
		this.setBlock(i + 11, j + 0, k + 9, Blocks.snow, world);
		this.setBlock(i + 11, j + 0, k + 10, Blocks.snow, world);
		this.setBlock(i + 11, j + 0, k + 11, Blocks.snow, world);
		this.setBlock(i + 11, j + 0, k + 12, Blocks.snow, world);
		this.setBlock(i + 11, j + 0, k + 13, Blocks.snow, world);
		this.setBlock(i + 11, j + 0, k + 14, Blocks.snow, world);
		this.setBlock(i + 11, j + 0, k + 15, Blocks.snow, world);
		this.setBlock(i + 11, j + 0, k + 16, Blocks.snow, world);
		this.setBlock(i + 11, j + 0, k + 17, Blocks.snow, world);
		this.setBlock(i + 11, j + 0, k + 18, Blocks.snow, world);
		this.setBlock(i + 11, j + 0, k + 19, Blocks.snow, world);
		this.setBlock(i + 11, j + 0, k + 20, Blocks.snow, world);
		this.setBlock(i + 11, j + 0, k + 21, Blocks.snow, world);
		this.setBlock(i + 11, j + 0, k + 22, Blocks.snow, world);
		this.setBlock(i + 11, j + 0, k + 23, Blocks.snow, world);
		this.setBlock(i + 11, j + 0, k + 24, Blocks.snow, world);
		this.setBlock(i + 11, j + 0, k + 25, Blocks.snow, world);
		this.setBlock(i + 11, j + 0, k + 26, Blocks.snow, world);
		this.setBlock(i + 11, j + 0, k + 27, Blocks.snow, world);
		this.setBlock(i + 11, j + 0, k + 28, Blocks.snow, world);
		this.setBlock(i + 11, j + 0, k + 29, Blocks.snow, world);
		this.setBlock(i + 11, j + 0, k + 30, Blocks.snow, world);
		this.setBlock(i + 11, j + 0, k + 31, Blocks.snow, world);
		this.setBlock(i + 11, j + 33, k + 12, BlockRegistry.void_block_1, world);
		this.setBlock(i + 11, j + 33, k + 13, BlockRegistry.silver_ore_1, world);
		this.setBlock(i + 11, j + 33, k + 14, BlockRegistry.void_block_1, world);
		this.setBlock(i + 11, j + 33, k + 15, BlockRegistry.void_block_1, world);
		this.setBlock(i + 11, j + 33, k + 16, BlockRegistry.void_block_1, world);
		this.setBlock(i + 11, j + 33, k + 17, BlockRegistry.void_block_1, world);
		this.setBlock(i + 11, j + 33, k + 18, BlockRegistry.silver_ore_1, world);
		this.setBlock(i + 11, j + 33, k + 19, BlockRegistry.void_block_1, world);
		this.setBlock(i + 11, j + 34, k + 11, BlockRegistry.void_block_1, world);
		this.setBlock(i + 11, j + 34, k + 12, BlockRegistry.silver_ore_1, world);
		this.setBlock(i + 11, j + 34, k + 13, BlockRegistry.void_block_1, world);
		this.setBlock(i + 11, j + 34, k + 14, BlockRegistry.void_block_1, world);
		this.setBlock(i + 11, j + 34, k + 15, BlockRegistry.void_block_1, world);
		this.setBlock(i + 11, j + 34, k + 16, BlockRegistry.void_block_1, world);
		this.setBlock(i + 11, j + 34, k + 17, BlockRegistry.void_block_1, world);
		this.setBlock(i + 11, j + 34, k + 18, BlockRegistry.void_block_1, world);
		this.setBlock(i + 11, j + 34, k + 19, BlockRegistry.silver_ore_1, world);
		this.setBlock(i + 11, j + 34, k + 20, BlockRegistry.void_block_1, world);
		this.setBlock(i + 12, j + 0, k + 0, Blocks.snow, world);
		this.setBlock(i + 12, j + 0, k + 1, Blocks.snow, world);
		this.setBlock(i + 12, j + 0, k + 2, Blocks.snow, world);
		this.setBlock(i + 12, j + 0, k + 3, Blocks.snow, world);
		this.setBlock(i + 12, j + 0, k + 4, Blocks.snow, world);
		this.setBlock(i + 12, j + 0, k + 5, Blocks.snow, world);
		this.setBlock(i + 12, j + 0, k + 6, Blocks.snow, world);
		this.setBlock(i + 12, j + 0, k + 7, Blocks.snow, world);
		this.setBlock(i + 12, j + 0, k + 8, Blocks.snow, world);
		this.setBlock(i + 12, j + 0, k + 9, Blocks.snow, world);
		this.setBlock(i + 12, j + 0, k + 10, Blocks.snow, world);
		this.setBlock(i + 12, j + 0, k + 11, Blocks.snow, world);
		this.setBlock(i + 12, j + 0, k + 12, Blocks.snow, world);
		this.setBlock(i + 12, j + 0, k + 13, Blocks.snow, world);
		this.setBlock(i + 12, j + 0, k + 14, Blocks.quartz_block, world);
		//1.8 update starting here silver blocks had a 3 or 5 and I replaced with world
		this.setBlock(i + 12, j + 0, k + 15, BlockRegistry.void_block_1, world);
		this.setBlock(i + 12, j + 0, k + 16, BlockRegistry.void_block_1, world);
		this.setBlock(i + 12, j + 0, k + 17, BlockRegistry.void_block_1, world);
		this.setBlock(i + 12, j + 0, k + 18, Blocks.snow, world);
		this.setBlock(i + 12, j + 0, k + 19, Blocks.snow, world);
		this.setBlock(i + 12, j + 0, k + 20, Blocks.snow, world);
		this.setBlock(i + 12, j + 0, k + 21, Blocks.snow, world);
		this.setBlock(i + 12, j + 0, k + 22, Blocks.snow, world);
		this.setBlock(i + 12, j + 0, k + 23, Blocks.snow, world);
		this.setBlock(i + 12, j + 0, k + 24, Blocks.snow, world);
		this.setBlock(i + 12, j + 0, k + 25, Blocks.snow, world);
		this.setBlock(i + 12, j + 0, k + 26, Blocks.snow, world);
		this.setBlock(i + 12, j + 0, k + 27, Blocks.snow, world);
		this.setBlock(i + 12, j + 0, k + 28, Blocks.snow, world);
		this.setBlock(i + 12, j + 0, k + 29, Blocks.snow, world);
		this.setBlock(i + 12, j + 0, k + 30, Blocks.snow, world);
		this.setBlock(i + 12, j + 0, k + 31, Blocks.snow, world);
		this.setBlock(i + 12, j + 1, k + 14, BlockRegistry.void_block_1, world);
		this.setBlock(i + 12, j + 1, k + 15, Blocks.sandstone_stairs, world);
		this.setBlock(i + 12, j + 1, k + 16, Blocks.sandstone_stairs, world);
		this.setBlock(i + 12, j + 1, k + 17, BlockRegistry.void_block_1, world);
		this.setBlock(i + 12, j + 33, k + 11, BlockRegistry.void_block_1, world);
		this.setBlock(i + 12, j + 33, k + 12, BlockRegistry.silver_ore_1, world);
		this.setBlock(i + 12, j + 33, k + 13, BlockRegistry.void_block_1, world);
		this.setBlock(i + 12, j + 33, k + 14, BlockRegistry.void_block_1, world);
		this.setBlock(i + 12, j + 33, k + 15, BlockRegistry.void_block_1, world);
		this.setBlock(i + 12, j + 33, k + 16, BlockRegistry.void_block_1, world);
		this.setBlock(i + 12, j + 33, k + 17, BlockRegistry.void_block_1, world);
		this.setBlock(i + 12, j + 33, k + 18, BlockRegistry.void_block_1, world);
		this.setBlock(i + 12, j + 33, k + 19, BlockRegistry.silver_ore_1, world);
		this.setBlock(i + 12, j + 33, k + 20, BlockRegistry.void_block_1, world);
		this.setBlock(i + 12, j + 34, k + 10, BlockRegistry.void_block_1, world);
		this.setBlock(i + 12, j + 34, k + 11, BlockRegistry.silver_ore_1, world);
		this.setBlock(i + 12, j + 34, k + 12, BlockRegistry.void_block_1, world);
		this.setBlock(i + 12, j + 34, k + 13, BlockRegistry.void_block_1, world);
		this.setBlock(i + 12, j + 34, k + 14, BlockRegistry.void_block_1, world);
		this.setBlock(i + 12, j + 34, k + 15, BlockRegistry.void_block_1, world);
		this.setBlock(i + 12, j + 34, k + 16, BlockRegistry.void_block_1, world);
		this.setBlock(i + 12, j + 34, k + 17, BlockRegistry.void_block_1, world);
		this.setBlock(i + 12, j + 34, k + 18, BlockRegistry.void_block_1, world);
		this.setBlock(i + 12, j + 34, k + 19, BlockRegistry.void_block_1, world);
		this.setBlock(i + 12, j + 34, k + 20, BlockRegistry.silver_ore_1, world);
		this.setBlock(i + 12, j + 34, k + 21, BlockRegistry.void_block_1, world);
		this.setBlock(i + 13, j + 0, k + 0, Blocks.snow, world);
		this.setBlock(i + 13, j + 0, k + 1, Blocks.snow, world);
		this.setBlock(i + 13, j + 0, k + 2, Blocks.snow, world);
		this.setBlock(i + 13, j + 0, k + 3, Blocks.snow, world);
		this.setBlock(i + 13, j + 0, k + 4, Blocks.snow, world);
		this.setBlock(i + 13, j + 0, k + 5, Blocks.snow, world);
		this.setBlock(i + 13, j + 0, k + 6, Blocks.snow, world);
		this.setBlock(i + 13, j + 0, k + 7, Blocks.snow, world);
		this.setBlock(i + 13, j + 0, k + 8, Blocks.snow, world);
		this.setBlock(i + 13, j + 0, k + 9, Blocks.snow, world);
		this.setBlock(i + 13, j + 0, k + 10, Blocks.snow, world);
		this.setBlock(i + 13, j + 0, k + 11, Blocks.snow, world);
		this.setBlock(i + 13, j + 0, k + 12, Blocks.snow, world);
		this.setBlock(i + 13, j + 0, k + 13, Blocks.quartz_block, world);
		this.setBlock(i + 13, j + 0, k + 14, Blocks.quartz_block, world);
		this.setBlock(i + 13, j + 0, k + 15, Blocks.quartz_block, world);
		this.setBlock(i + 13, j + 0, k + 16, Blocks.quartz_block, world);
		this.setBlock(i + 13, j + 0, k + 17, Blocks.quartz_block, world);
		this.setBlock(i + 13, j + 0, k + 18, BlockRegistry.void_block_1, world);
		this.setBlock(i + 13, j + 0, k + 19, Blocks.snow, world);
		this.setBlock(i + 13, j + 0, k + 20, Blocks.snow, world);
		this.setBlock(i + 13, j + 0, k + 21, Blocks.snow, world);
		this.setBlock(i + 13, j + 0, k + 22, Blocks.snow, world);
		this.setBlock(i + 13, j + 0, k + 23, Blocks.snow, world);
		this.setBlock(i + 13, j + 0, k + 24, Blocks.snow, world);
		this.setBlock(i + 13, j + 0, k + 25, Blocks.snow, world);
		this.setBlock(i + 13, j + 0, k + 26, Blocks.snow, world);
		this.setBlock(i + 13, j + 0, k + 27, Blocks.snow, world);
		this.setBlock(i + 13, j + 0, k + 28, Blocks.snow, world);
		this.setBlock(i + 13, j + 0, k + 29, Blocks.snow, world);
		this.setBlock(i + 13, j + 0, k + 30, Blocks.snow, world);
		this.setBlock(i + 13, j + 0, k + 31, Blocks.snow, world);
		this.setBlock(i + 13, j + 1, k + 13, BlockRegistry.void_block_1, world);
		this.setBlock(i + 13, j + 1, k + 14, Blocks.quartz_block, world);
		this.setBlock(i + 13, j + 1, k + 15, BlockRegistry.void_block_1, world);
		this.setBlock(i + 13, j + 1, k + 16, BlockRegistry.void_block_1, world);
		this.setBlock(i + 13, j + 1, k + 17, Blocks.quartz_block, world);
		this.setBlock(i + 13, j + 1, k + 18, BlockRegistry.void_block_1, world);
		this.setBlock(i + 13, j + 2, k + 14, BlockRegistry.void_block_1, world);
		this.setBlock(i + 13, j + 2, k + 15, Blocks.sandstone_stairs, world);
		this.setBlock(i + 13, j + 2, k + 16, Blocks.sandstone_stairs, world);
		this.setBlock(i + 13, j + 2, k + 17, BlockRegistry.void_block_1, world);
		this.setBlock(i + 13, j + 32, k + 11, BlockRegistry.void_block_1, world);
		this.setBlock(i + 13, j + 32, k + 12, BlockRegistry.silver_ore_1, world);
		this.setBlock(i + 13, j + 32, k + 13, BlockRegistry.void_block_1, world);
		this.setBlock(i + 13, j + 32, k + 14, BlockRegistry.void_block_1, world);
		this.setBlock(i + 13, j + 32, k + 15, BlockRegistry.void_block_1, world);
		this.setBlock(i + 13, j + 32, k + 16, BlockRegistry.void_block_1, world);
		this.setBlock(i + 13, j + 32, k + 17, BlockRegistry.void_block_1, world);
		this.setBlock(i + 13, j + 32, k + 18, BlockRegistry.void_block_1, world);
		this.setBlock(i + 13, j + 32, k + 19, BlockRegistry.silver_ore_1, world);
		this.setBlock(i + 13, j + 32, k + 20, BlockRegistry.void_block_1, world);
		this.setBlock(i + 13, j + 33, k + 10, BlockRegistry.void_block_1, world);
		this.setBlock(i + 13, j + 33, k + 11, BlockRegistry.silver_ore_1, world);
		this.setBlock(i + 13, j + 33, k + 18, BlockRegistry.void_block_1, world);
		this.setBlock(i + 13, j + 33, k + 19, BlockRegistry.void_block_1, world);
		this.setBlock(i + 13, j + 33, k + 20, BlockRegistry.silver_ore_1, world);
		this.setBlock(i + 13, j + 33, k + 21, BlockRegistry.void_block_1, world);
		this.setBlock(i + 13, j + 34, k + 9, BlockRegistry.void_block_1, world);
		this.setBlock(i + 13, j + 34, k + 10, BlockRegistry.silver_ore_1, world);
		this.setBlock(i + 13, j + 34, k + 15, BlockRegistry.void_block_1, world);
		this.setBlock(i + 13, j + 34, k + 16, BlockRegistry.void_block_1, world);
		this.setBlock(i + 13, j + 34, k + 21, BlockRegistry.silver_ore_1, world);
		this.setBlock(i + 13, j + 34, k + 22, BlockRegistry.void_block_1, world);
		this.setBlock(i + 14, j + 0, k + 0, Blocks.snow, world);
		this.setBlock(i + 14, j + 0, k + 1, Blocks.snow, world);
		this.setBlock(i + 14, j + 0, k + 2, Blocks.snow, world);
		this.setBlock(i + 14, j + 0, k + 3, Blocks.snow, world);
		this.setBlock(i + 14, j + 0, k + 4, Blocks.snow, world);
		this.setBlock(i + 14, j + 0, k + 5, Blocks.snow, world);
		this.setBlock(i + 14, j + 0, k + 6, Blocks.snow, world);
		this.setBlock(i + 14, j + 0, k + 7, Blocks.snow, world);
		this.setBlock(i + 14, j + 0, k + 8, Blocks.snow, world);
		this.setBlock(i + 14, j + 0, k + 9, Blocks.snow, world);
		this.setBlock(i + 14, j + 0, k + 10, Blocks.snow, world);
		this.setBlock(i + 14, j + 0, k + 11, Blocks.snow, world);
		this.setBlock(i + 14, j + 0, k + 12, BlockRegistry.void_block_1, world);
		this.setBlock(i + 14, j + 0, k + 13, Blocks.quartz_block, world);
		this.setBlock(i + 14, j + 0, k + 14, Blocks.quartz_block, world);
		this.setBlock(i + 14, j + 0, k + 15, Blocks.quartz_block, world);
		this.setBlock(i + 14, j + 0, k + 16, Blocks.quartz_block, world);
		this.setBlock(i + 14, j + 0, k + 17, Blocks.quartz_block, world);
		this.setBlock(i + 14, j + 0, k + 18, BlockRegistry.void_block_1, world);
		this.setBlock(i + 14, j + 0, k + 19, Blocks.quartz_block, world);
		this.setBlock(i + 14, j + 0, k + 20, Blocks.snow, world);
		this.setBlock(i + 14, j + 0, k + 21, Blocks.snow, world);
		this.setBlock(i + 14, j + 0, k + 22, Blocks.snow, world);
		this.setBlock(i + 14, j + 0, k + 23, Blocks.snow, world);
		this.setBlock(i + 14, j + 0, k + 24, Blocks.snow, world);
		this.setBlock(i + 14, j + 0, k + 25, Blocks.snow, world);
		this.setBlock(i + 14, j + 0, k + 26, Blocks.snow, world);
		this.setBlock(i + 14, j + 0, k + 27, Blocks.snow, world);
		this.setBlock(i + 14, j + 0, k + 28, Blocks.snow, world);
		this.setBlock(i + 14, j + 0, k + 29, Blocks.snow, world);
		this.setBlock(i + 14, j + 0, k + 30, Blocks.snow, world);
		this.setBlock(i + 14, j + 0, k + 31, Blocks.snow, world);
		this.setBlock(i + 14, j + 1, k + 12, BlockRegistry.void_block_1, world);
		this.setBlock(i + 14, j + 1, k + 13, Blocks.quartz_block, world);
		this.setBlock(i + 14, j + 1, k + 14, Blocks.quartz_block, world);
		this.setBlock(i + 14, j + 1, k + 15, Blocks.quartz_block, world);
		this.setBlock(i + 14, j + 1, k + 16, BlockRegistry.void_block_1, world);
		this.setBlock(i + 14, j + 1, k + 17, Blocks.quartz_block, world);
		this.setBlock(i + 14, j + 1, k + 18, Blocks.quartz_block, world);
		this.setBlock(i + 14, j + 1, k + 19, BlockRegistry.void_block_1, world);
		this.setBlock(i + 14, j + 2, k + 13, BlockRegistry.void_block_1, world);
		this.setBlock(i + 14, j + 2, k + 14, Blocks.quartz_block, world);
		this.setBlock(i + 14, j + 2, k + 15, Blocks.quartz_block, world);
		this.setBlock(i + 14, j + 2, k + 16, Blocks.quartz_block, world);
		this.setBlock(i + 14, j + 2, k + 17, Blocks.quartz_block, world);
		this.setBlock(i + 14, j + 2, k + 18, BlockRegistry.void_block_1, world);
		this.setBlock(i + 14, j + 3, k + 14, BlockRegistry.void_block_1, world);
		this.setBlock(i + 14, j + 3, k + 15, Blocks.sandstone_stairs, world);
		this.setBlock(i + 14, j + 3, k + 16, Blocks.sandstone_stairs, world);
		this.setBlock(i + 14, j + 3, k + 17, BlockRegistry.void_block_1, world);
		this.setBlock(i + 14, j + 32, k + 10, BlockRegistry.void_block_1, world);
		this.setBlock(i + 14, j + 32, k + 11, BlockRegistry.silver_ore_1, world);
		this.setBlock(i + 14, j + 32, k + 12, BlockRegistry.void_block_1, world);
		this.setBlock(i + 14, j + 32, k + 13, BlockRegistry.void_block_1, world);
		this.setBlock(i + 14, j + 32, k + 14, BlockRegistry.void_block_1, world);
		this.setBlock(i + 14, j + 32, k + 15, BlockRegistry.void_block_1, world);
		this.setBlock(i + 14, j + 32, k + 16, BlockRegistry.void_block_1, world);
		this.setBlock(i + 14, j + 32, k + 17, BlockRegistry.void_block_1, world);
		this.setBlock(i + 14, j + 32, k + 18, BlockRegistry.void_block_1, world);
		this.setBlock(i + 14, j + 32, k + 19, BlockRegistry.void_block_1, world);
		this.setBlock(i + 14, j + 32, k + 20, BlockRegistry.silver_ore_1, world);
		this.setBlock(i + 14, j + 32, k + 21, BlockRegistry.void_block_1, world);
		this.setBlock(i + 14, j + 33, k + 9, BlockRegistry.void_block_1, world);
		this.setBlock(i + 14, j + 33, k + 10, BlockRegistry.silver_ore_1, world);
		this.setBlock(i + 14, j + 33, k + 18, BlockRegistry.void_block_1, world);
		this.setBlock(i + 14, j + 33, k + 19, BlockRegistry.void_block_1, world);
		this.setBlock(i + 14, j + 33, k + 20, BlockRegistry.void_block_1, world);
		this.setBlock(i + 14, j + 33, k + 21, BlockRegistry.silver_ore_1, world);
		this.setBlock(i + 14, j + 33, k + 22, BlockRegistry.void_block_1, world);
		this.setBlock(i + 14, j + 34, k + 8, BlockRegistry.void_block_1, world);
		this.setBlock(i + 14, j + 34, k + 9, BlockRegistry.silver_ore_1, world);
		this.setBlock(i + 14, j + 34, k + 15, BlockRegistry.void_block_1, world);
		this.setBlock(i + 14, j + 34, k + 16, BlockRegistry.void_block_1, world);
		this.setBlock(i + 14, j + 34, k + 22, BlockRegistry.silver_ore_1, world);
		this.setBlock(i + 14, j + 34, k + 23, BlockRegistry.void_block_1, world);
		this.setBlock(i + 15, j + 0, k + 0, Blocks.snow, world);
		this.setBlock(i + 15, j + 0, k + 1, Blocks.snow, world);
		this.setBlock(i + 15, j + 0, k + 2, Blocks.snow, world);
		this.setBlock(i + 15, j + 0, k + 3, Blocks.snow, world);
		this.setBlock(i + 15, j + 0, k + 4, Blocks.snow, world);
		this.setBlock(i + 15, j + 0, k + 5, Blocks.snow, world);
		this.setBlock(i + 15, j + 0, k + 6, Blocks.snow, world);
		this.setBlock(i + 15, j + 0, k + 7, Blocks.snow, world);
		this.setBlock(i + 15, j + 0, k + 8, Blocks.snow, world);
		this.setBlock(i + 15, j + 0, k + 9, Blocks.snow, world);
		this.setBlock(i + 15, j + 0, k + 10, Blocks.snow, world);
		this.setBlock(i + 15, j + 0, k + 11, Blocks.snow, world);
		this.setBlock(i + 15, j + 0, k + 12, Blocks.snow, world);
		this.setBlock(i + 15, j + 0, k + 13, BlockRegistry.void_block_1, world);
		this.setBlock(i + 15, j + 0, k + 14, Blocks.quartz_block, world);
		this.setBlock(i + 15, j + 0, k + 15, Blocks.quartz_block, world);
		this.setBlock(i + 15, j + 0, k + 16, Blocks.quartz_block, world);
		this.setBlock(i + 15, j + 0, k + 17, Blocks.quartz_block, world);
		this.setBlock(i + 15, j + 0, k + 18, BlockRegistry.void_block_1, world);
		this.setBlock(i + 15, j + 0, k + 19, BlockRegistry.void_block_1, world);
		this.setBlock(i + 15, j + 0, k + 20, Blocks.quartz_block, world);
		this.setBlock(i + 15, j + 0, k + 21, Blocks.snow, world);
		this.setBlock(i + 15, j + 0, k + 22, Blocks.snow, world);
		this.setBlock(i + 15, j + 0, k + 23, Blocks.snow, world);
		this.setBlock(i + 15, j + 0, k + 24, Blocks.snow, world);
		this.setBlock(i + 15, j + 0, k + 25, Blocks.snow, world);
		this.setBlock(i + 15, j + 0, k + 26, Blocks.snow, world);
		this.setBlock(i + 15, j + 0, k + 27, Blocks.snow, world);
		this.setBlock(i + 15, j + 0, k + 28, Blocks.snow, world);
		this.setBlock(i + 15, j + 0, k + 29, Blocks.snow, world);
		this.setBlock(i + 15, j + 0, k + 30, Blocks.snow, world);
		this.setBlock(i + 15, j + 0, k + 31, Blocks.snow, world);
		this.setBlock(i + 15, j + 1, k + 11, BlockRegistry.void_block_1, world);
		this.setBlock(i + 15, j + 1, k + 12, Blocks.quartz_block, world);
		this.setBlock(i + 15, j + 1, k + 13, Blocks.quartz_block, world);
		this.setBlock(i + 15, j + 1, k + 14, Blocks.quartz_block, world);
		this.setBlock(i + 15, j + 1, k + 15, Blocks.quartz_block, world);
		this.setBlock(i + 15, j + 1, k + 16, Blocks.quartz_block, world);
		this.setBlock(i + 15, j + 1, k + 17, Blocks.quartz_block, world);
		this.setBlock(i + 15, j + 1, k + 18, Blocks.quartz_block, world);
		this.setBlock(i + 15, j + 1, k + 19, Blocks.quartz_block, world);
		this.setBlock(i + 15, j + 1, k + 20, BlockRegistry.void_block_1, world);
		this.setBlock(i + 15, j + 2, k + 12, BlockRegistry.void_block_1, world);
		this.setBlock(i + 15, j + 2, k + 13, Blocks.quartz_block, world);
		this.setBlock(i + 15, j + 2, k + 14, Blocks.quartz_block, world);
		this.setBlock(i + 15, j + 2, k + 15, Blocks.quartz_block, world);
		this.setBlock(i + 15, j + 2, k + 16, Blocks.quartz_block, world);
		this.setBlock(i + 15, j + 2, k + 17, Blocks.quartz_block, world);
		this.setBlock(i + 15, j + 2, k + 18, Blocks.quartz_block, world);
		this.setBlock(i + 15, j + 2, k + 19, BlockRegistry.void_block_1, world);
		this.setBlock(i + 15, j + 3, k + 13, BlockRegistry.void_block_1, world);
		this.setBlock(i + 15, j + 3, k + 14, Blocks.quartz_block, world);
		this.setBlock(i + 15, j + 3, k + 15, ModFluids.rud_block, world);
		this.setBlock(i + 15, j + 3, k + 16, Blocks.quartz_block, world);
		this.setBlock(i + 15, j + 3, k + 17, Blocks.quartz_block, world);
		this.setBlock(i + 15, j + 3, k + 18, BlockRegistry.void_block_1, world);
		this.setBlock(i + 15, j + 4, k + 14, BlockRegistry.void_block_1, world);
		this.setBlock(i + 15, j + 4, k + 15, Blocks.sandstone_stairs, world);
		this.setBlock(i + 15, j + 4, k + 16, Blocks.sandstone_stairs, world);
		this.setBlock(i + 15, j + 4, k + 17, BlockRegistry.void_block_1, world);
		this.setBlock(i + 15, j + 31, k + 10, BlockRegistry.void_block_1, world);
		this.setBlock(i + 15, j + 31, k + 11, BlockRegistry.silver_ore_1, world);
		this.setBlock(i + 15, j + 31, k + 12, BlockRegistry.void_block_1, world);
		this.setBlock(i + 15, j + 31, k + 13, BlockRegistry.void_block_1, world);
		this.setBlock(i + 15, j + 31, k + 14, BlockRegistry.void_block_1, world);
		this.setBlock(i + 15, j + 31, k + 15, BlockRegistry.void_block_1, world);
		this.setBlock(i + 15, j + 31, k + 16, BlockRegistry.void_block_1, world);
		this.setBlock(i + 15, j + 31, k + 17, BlockRegistry.void_block_1, world);
		this.setBlock(i + 15, j + 31, k + 18, BlockRegistry.void_block_1, world);
		this.setBlock(i + 15, j + 31, k + 19, BlockRegistry.void_block_1, world);
		this.setBlock(i + 15, j + 31, k + 20, BlockRegistry.silver_ore_1, world);
		this.setBlock(i + 15, j + 31, k + 21, BlockRegistry.void_block_1, world);
		this.setBlock(i + 15, j + 32, k + 9, BlockRegistry.void_block_1, world);
		this.setBlock(i + 15, j + 32, k + 10, BlockRegistry.silver_ore_1, world);
		this.setBlock(i + 15, j + 32, k + 21, BlockRegistry.silver_ore_1, world);
		this.setBlock(i + 15, j + 32, k + 22, BlockRegistry.void_block_1, world);
		this.setBlock(i + 15, j + 33, k + 8, BlockRegistry.void_block_1, world);
		this.setBlock(i + 15, j + 33, k + 9, BlockRegistry.silver_ore_1, world);
		this.setBlock(i + 15, j + 33, k + 18, BlockRegistry.void_block_1, world);
		this.setBlock(i + 15, j + 33, k + 19, BlockRegistry.void_block_1, world);
		this.setBlock(i + 15, j + 33, k + 20, BlockRegistry.void_block_1, world);
		this.setBlock(i + 15, j + 33, k + 21, BlockRegistry.void_block_1, world);
		this.setBlock(i + 15, j + 33, k + 22, BlockRegistry.silver_ore_1, world);
		this.setBlock(i + 15, j + 33, k + 23, BlockRegistry.void_block_1, world);
		this.setBlock(i + 15, j + 34, k + 7, BlockRegistry.void_block_1, world);
		this.setBlock(i + 15, j + 34, k + 8, BlockRegistry.silver_ore_1, world);
		this.setBlock(i + 15, j + 34, k + 15, BlockRegistry.void_block_1, world);
		this.setBlock(i + 15, j + 34, k + 16, BlockRegistry.void_block_1, world);
		this.setBlock(i + 15, j + 34, k + 23, BlockRegistry.silver_ore_1, world);
		this.setBlock(i + 15, j + 34, k + 24, BlockRegistry.void_block_1, world);
		this.setBlock(i + 16, j + 0, k + 0, Blocks.snow, world);
		this.setBlock(i + 16, j + 0, k + 1, Blocks.snow, world);
		this.setBlock(i + 16, j + 0, k + 2, Blocks.snow, world);
		this.setBlock(i + 16, j + 0, k + 3, Blocks.snow, world);
		this.setBlock(i + 16, j + 0, k + 4, Blocks.snow, world);
		this.setBlock(i + 16, j + 0, k + 5, Blocks.snow, world);
		this.setBlock(i + 16, j + 0, k + 6, Blocks.snow, world);
		this.setBlock(i + 16, j + 0, k + 7, Blocks.snow, world);
		this.setBlock(i + 16, j + 0, k + 8, Blocks.snow, world);
		this.setBlock(i + 16, j + 0, k + 9, Blocks.snow, world);
		this.setBlock(i + 16, j + 0, k + 10, Blocks.snow, world);
		this.setBlock(i + 16, j + 0, k + 11, Blocks.snow, world);
		this.setBlock(i + 16, j + 0, k + 12, Blocks.snow, world);
		this.setBlock(i + 16, j + 0, k + 13, Blocks.quartz_block, world);
		this.setBlock(i + 16, j + 0, k + 14, Blocks.quartz_block, world);
		this.setBlock(i + 16, j + 0, k + 15, BlockRegistry.void_block_1, world);
		this.setBlock(i + 16, j + 0, k + 16, BlockRegistry.void_block_1, world);
		this.setBlock(i + 16, j + 0, k + 17, BlockRegistry.void_block_1, world);
		this.setBlock(i + 16, j + 0, k + 18, Blocks.quartz_block, world);
		this.setBlock(i + 16, j + 0, k + 19, Blocks.quartz_block, world);
		this.setBlock(i + 16, j + 0, k + 20, Blocks.quartz_block, world);
		this.setBlock(i + 16, j + 0, k + 21, Blocks.quartz_block, world);
		this.setBlock(i + 16, j + 0, k + 22, Blocks.snow, world);
		this.setBlock(i + 16, j + 0, k + 23, Blocks.snow, world);
		this.setBlock(i + 16, j + 0, k + 24, Blocks.snow, world);
		this.setBlock(i + 16, j + 0, k + 25, Blocks.snow, world);
		this.setBlock(i + 16, j + 0, k + 26, Blocks.snow, world);
		this.setBlock(i + 16, j + 0, k + 27, Blocks.snow, world);
		this.setBlock(i + 16, j + 0, k + 28, Blocks.snow, world);
		this.setBlock(i + 16, j + 0, k + 29, Blocks.snow, world);
		this.setBlock(i + 16, j + 0, k + 30, Blocks.snow, world);
		this.setBlock(i + 16, j + 0, k + 31, Blocks.snow, world);
		this.setBlock(i + 16, j + 1, k + 10, BlockRegistry.void_block_1, world);
		this.setBlock(i + 16, j + 1, k + 11, Blocks.quartz_block, world);
		this.setBlock(i + 16, j + 1, k + 12, Blocks.quartz_block, world);
		this.setBlock(i + 16, j + 1, k + 13, Blocks.quartz_block, world);
		this.setBlock(i + 16, j + 1, k + 14, Blocks.quartz_block, world);
		this.setBlock(i + 16, j + 1, k + 15, Blocks.quartz_block, world);
		this.setBlock(i + 16, j + 1, k + 16, Blocks.quartz_block, world);
		this.setBlock(i + 16, j + 1, k + 17, Blocks.quartz_block, world);
		this.setBlock(i + 16, j + 1, k + 18, Blocks.quartz_block, world);
		this.setBlock(i + 16, j + 1, k + 19, Blocks.quartz_block, world);
		this.setBlock(i + 16, j + 1, k + 20, Blocks.quartz_block, world);
		this.setBlock(i + 16, j + 1, k + 21, BlockRegistry.void_block_1, world);
		this.setBlock(i + 16, j + 2, k + 11, BlockRegistry.void_block_1, world);
		this.setBlock(i + 16, j + 2, k + 12, Blocks.quartz_block, world);
		this.setBlock(i + 16, j + 2, k + 13, Blocks.quartz_block, world);
		this.setBlock(i + 16, j + 2, k + 14, Blocks.quartz_block, world);
		this.setBlock(i + 16, j + 2, k + 15, Blocks.quartz_block, world);
		this.setBlock(i + 16, j + 2, k + 16, Blocks.quartz_block, world);
		this.setBlock(i + 16, j + 2, k + 17, Blocks.quartz_block, world);
		this.setBlock(i + 16, j + 2, k + 18, Blocks.quartz_block, world);
		this.setBlock(i + 16, j + 2, k + 19, Blocks.quartz_block, world);
		this.setBlock(i + 16, j + 2, k + 20, BlockRegistry.void_block_1, world);
		this.setBlock(i + 16, j + 3, k + 12, BlockRegistry.void_block_1, world);
		this.setBlock(i + 16, j + 3, k + 13, Blocks.quartz_block, world);
		this.setBlock(i + 16, j + 3, k + 14, Blocks.quartz_block, world);
		this.setBlock(i + 16, j + 3, k + 15, Blocks.quartz_block, world);
		this.setBlock(i + 16, j + 3, k + 16, Blocks.quartz_block, world);
		this.setBlock(i + 16, j + 3, k + 17, Blocks.quartz_block, world);
		this.setBlock(i + 16, j + 3, k + 18, Blocks.quartz_block, world);
		this.setBlock(i + 16, j + 3, k + 19, BlockRegistry.void_block_1, world);
		this.setBlock(i + 16, j + 4, k + 13, BlockRegistry.void_block_1, world);
		this.setBlock(i + 16, j + 4, k + 14, Blocks.quartz_block, world);
		this.setBlock(i + 16, j + 4, k + 15, ModFluids.rud_block, world);
		this.setBlock(i + 16, j + 4, k + 16, ModFluids.rud_block, world);
		this.setBlock(i + 16, j + 4, k + 17, Blocks.quartz_block, world);
		this.setBlock(i + 16, j + 4, k + 18, BlockRegistry.void_block_1, world);
		this.setBlock(i + 16, j + 5, k + 14, BlockRegistry.void_block_1, world);
		this.setBlock(i + 16, j + 5, k + 15, Blocks.sandstone_stairs, world);
		this.setBlock(i + 16, j + 5, k + 16, Blocks.sandstone_stairs, world);
		this.setBlock(i + 16, j + 5, k + 17, BlockRegistry.void_block_1, world);
		this.setBlock(i + 16, j + 30, k + 10, BlockRegistry.void_block_1, world);
		this.setBlock(i + 16, j + 30, k + 11, BlockRegistry.silver_ore_1, world);
		this.setBlock(i + 16, j + 30, k + 12, BlockRegistry.void_block_1, world);
		this.setBlock(i + 16, j + 30, k + 13, BlockRegistry.void_block_1, world);
		this.setBlock(i + 16, j + 30, k + 14, BlockRegistry.void_block_1, world);
		this.setBlock(i + 16, j + 30, k + 15, BlockRegistry.void_block_1, world);
		this.setBlock(i + 16, j + 30, k + 16, BlockRegistry.void_block_1, world);
		this.setBlock(i + 16, j + 30, k + 17, BlockRegistry.void_block_1, world);
		this.setBlock(i + 16, j + 30, k + 18, BlockRegistry.void_block_1, world);
		this.setBlock(i + 16, j + 30, k + 19, BlockRegistry.void_block_1, world);
		this.setBlock(i + 16, j + 30, k + 20, BlockRegistry.silver_ore_1, world);
		this.setBlock(i + 16, j + 30, k + 21, BlockRegistry.void_block_1, world);
		this.setBlock(i + 16, j + 31, k + 9, BlockRegistry.void_block_1, world);
		this.setBlock(i + 16, j + 31, k + 10, BlockRegistry.silver_ore_1, world);
		this.setBlock(i + 16, j + 31, k + 11, BlockRegistry.void_block_1, world);
		this.setBlock(i + 16, j + 31, k + 12, BlockRegistry.void_block_1, world);
		this.setBlock(i + 16, j + 31, k + 13, BlockRegistry.void_block_1, world);
		this.setBlock(i + 16, j + 31, k + 14, BlockRegistry.void_block_1, world);
		this.setBlock(i + 16, j + 31, k + 15, BlockRegistry.void_block_1, world);
		this.setBlock(i + 16, j + 31, k + 16, BlockRegistry.void_block_1, world);
		this.setBlock(i + 16, j + 31, k + 17, BlockRegistry.void_block_1, world);
		this.setBlock(i + 16, j + 31, k + 18, BlockRegistry.void_block_1, world);
		this.setBlock(i + 16, j + 31, k + 19, BlockRegistry.void_block_1, world);
		this.setBlock(i + 16, j + 31, k + 20, BlockRegistry.void_block_1, world);
		this.setBlock(i + 16, j + 31, k + 21, BlockRegistry.silver_ore_1, world);
		this.setBlock(i + 16, j + 31, k + 22, BlockRegistry.void_block_1, world);
		this.setBlock(i + 16, j + 32, k + 8, BlockRegistry.void_block_1, world);
		this.setBlock(i + 16, j + 32, k + 9, BlockRegistry.silver_ore_1, world);
		this.setBlock(i + 16, j + 32, k + 22, BlockRegistry.silver_ore_1, world);
		this.setBlock(i + 16, j + 32, k + 23, BlockRegistry.void_block_1, world);
		this.setBlock(i + 16, j + 33, k + 7, BlockRegistry.void_block_1, world);
		this.setBlock(i + 16, j + 33, k + 8, BlockRegistry.silver_ore_1, world);
		this.setBlock(i + 16, j + 33, k + 18, BlockRegistry.void_block_1, world);
		this.setBlock(i + 16, j + 33, k + 19, BlockRegistry.void_block_1, world);
		this.setBlock(i + 16, j + 33, k + 20, BlockRegistry.void_block_1, world);
		this.setBlock(i + 16, j + 33, k + 21, BlockRegistry.void_block_1, world);
		this.setBlock(i + 16, j + 33, k + 22, BlockRegistry.void_block_1, world);
		this.setBlock(i + 16, j + 33, k + 23, BlockRegistry.silver_ore_1, world);
		this.setBlock(i + 16, j + 33, k + 24, BlockRegistry.void_block_1, world);
		this.setBlock(i + 16, j + 34, k + 6, BlockRegistry.void_block_1, world);
		this.setBlock(i + 16, j + 34, k + 7, BlockRegistry.silver_ore_1, world);
		this.setBlock(i + 16, j + 34, k + 15, BlockRegistry.void_block_1, world);
		this.setBlock(i + 16, j + 34, k + 16, BlockRegistry.void_block_1, world);
		this.setBlock(i + 16, j + 34, k + 24, BlockRegistry.silver_ore_1, world);
		this.setBlock(i + 16, j + 34, k + 25, BlockRegistry.void_block_1, world);
		this.setBlock(i + 17, j + 0, k + 0, Blocks.snow, world);
		this.setBlock(i + 17, j + 0, k + 1, Blocks.snow, world);
		this.setBlock(i + 17, j + 0, k + 2, Blocks.snow, world);
		this.setBlock(i + 17, j + 0, k + 3, Blocks.snow, world);
		this.setBlock(i + 17, j + 0, k + 4, Blocks.snow, world);
		this.setBlock(i + 17, j + 0, k + 5, Blocks.snow, world);
		this.setBlock(i + 17, j + 0, k + 6, Blocks.snow, world);
		this.setBlock(i + 17, j + 0, k + 7, Blocks.snow, world);
		this.setBlock(i + 17, j + 0, k + 8, Blocks.snow, world);
		this.setBlock(i + 17, j + 0, k + 9, Blocks.snow, world);
		this.setBlock(i + 17, j + 0, k + 10, Blocks.snow, world);
		this.setBlock(i + 17, j + 0, k + 11, Blocks.snow, world);
		this.setBlock(i + 17, j + 0, k + 12, Blocks.snow, world);
		this.setBlock(i + 17, j + 0, k + 13, Blocks.quartz_block, world);
		this.setBlock(i + 17, j + 0, k + 14, Blocks.quartz_block, world);
		this.setBlock(i + 17, j + 0, k + 15, BlockRegistry.void_block_1, world);
		this.setBlock(i + 17, j + 0, k + 16, BlockRegistry.void_block_1, world);
		this.setBlock(i + 17, j + 0, k + 17, BlockRegistry.void_block_1, world);
		this.setBlock(i + 17, j + 0, k + 18, Blocks.quartz_block, world);
		this.setBlock(i + 17, j + 0, k + 19, Blocks.quartz_block, world);
		this.setBlock(i + 17, j + 0, k + 20, Blocks.quartz_block, world);
		this.setBlock(i + 17, j + 0, k + 21, Blocks.quartz_block, world);
		this.setBlock(i + 17, j + 0, k + 22, Blocks.quartz_block, world);
		this.setBlock(i + 17, j + 0, k + 23, Blocks.snow, world);
		this.setBlock(i + 17, j + 0, k + 24, Blocks.snow, world);
		this.setBlock(i + 17, j + 0, k + 25, Blocks.snow, world);
		this.setBlock(i + 17, j + 0, k + 26, Blocks.snow, world);
		this.setBlock(i + 17, j + 0, k + 27, Blocks.snow, world);
		this.setBlock(i + 17, j + 0, k + 28, Blocks.snow, world);
		this.setBlock(i + 17, j + 0, k + 29, Blocks.snow, world);
		this.setBlock(i + 17, j + 0, k + 30, Blocks.snow, world);
		this.setBlock(i + 17, j + 0, k + 31, Blocks.snow, world);
		this.setBlock(i + 17, j + 1, k + 9, BlockRegistry.void_block_1, world);
		this.setBlock(i + 17, j + 1, k + 10, Blocks.quartz_block, world);
		this.setBlock(i + 17, j + 1, k + 11, Blocks.quartz_block, world);
		this.setBlock(i + 17, j + 1, k + 12, Blocks.quartz_block, world);
		this.setBlock(i + 17, j + 1, k + 13, Blocks.quartz_block, world);
		this.setBlock(i + 17, j + 1, k + 14, Blocks.quartz_block, world);
		this.setBlock(i + 17, j + 1, k + 15, Blocks.quartz_block, world);
		this.setBlock(i + 17, j + 1, k + 16, Blocks.quartz_block, world);
		this.setBlock(i + 17, j + 1, k + 17, Blocks.quartz_block, world);
		this.setBlock(i + 17, j + 1, k + 18, Blocks.quartz_block, world);
		this.setBlock(i + 17, j + 1, k + 19, Blocks.quartz_block, world);
		this.setBlock(i + 17, j + 1, k + 20, Blocks.quartz_block, world);
		this.setBlock(i + 17, j + 1, k + 21, Blocks.quartz_block, world);
		this.setBlock(i + 17, j + 1, k + 22, BlockRegistry.void_block_1, world);
		this.setBlock(i + 17, j + 2, k + 10, BlockRegistry.void_block_1, world);
		this.setBlock(i + 17, j + 2, k + 11, Blocks.quartz_block, world);
		this.setBlock(i + 17, j + 2, k + 12, Blocks.quartz_block, world);
		this.setBlock(i + 17, j + 2, k + 13, Blocks.quartz_block, world);
		this.setBlock(i + 17, j + 2, k + 14, Blocks.quartz_block, world);
		this.setBlock(i + 17, j + 2, k + 15, Blocks.quartz_block, world);
		this.setBlock(i + 17, j + 2, k + 16, Blocks.quartz_block, world);
		this.setBlock(i + 17, j + 2, k + 17, Blocks.quartz_block, world);
		this.setBlock(i + 17, j + 2, k + 18, Blocks.quartz_block, world);
		this.setBlock(i + 17, j + 2, k + 19, Blocks.quartz_block, world);
		this.setBlock(i + 17, j + 2, k + 20, Blocks.quartz_block, world);
		this.setBlock(i + 17, j + 2, k + 21, BlockRegistry.void_block_1, world);
		this.setBlock(i + 17, j + 3, k + 11, BlockRegistry.void_block_1, world);
		this.setBlock(i + 17, j + 3, k + 12, Blocks.quartz_block, world);
		this.setBlock(i + 17, j + 3, k + 13, Blocks.quartz_block, world);
		this.setBlock(i + 17, j + 3, k + 14, Blocks.quartz_block, world);
		this.setBlock(i + 17, j + 3, k + 15, Blocks.quartz_block, world);
		this.setBlock(i + 17, j + 3, k + 16, Blocks.quartz_block, world);
		this.setBlock(i + 17, j + 3, k + 17, Blocks.quartz_block, world);
		this.setBlock(i + 17, j + 3, k + 18, Blocks.quartz_block, world);
		this.setBlock(i + 17, j + 3, k + 19, Blocks.quartz_block, world);
		this.setBlock(i + 17, j + 3, k + 20, BlockRegistry.void_block_1, world);
		this.setBlock(i + 17, j + 4, k + 12, BlockRegistry.void_block_1, world);
		this.setBlock(i + 17, j + 4, k + 13, Blocks.quartz_block, world);
		this.setBlock(i + 17, j + 4, k + 14, Blocks.quartz_block, world);
		this.setBlock(i + 17, j + 4, k + 15, Blocks.quartz_block, world);
		this.setBlock(i + 17, j + 4, k + 16, Blocks.quartz_block, world);
		this.setBlock(i + 17, j + 4, k + 17, Blocks.quartz_block, world);
		this.setBlock(i + 17, j + 4, k + 18, Blocks.quartz_block, world);
		this.setBlock(i + 17, j + 4, k + 19, BlockRegistry.void_block_1, world);
		this.setBlock(i + 17, j + 5, k + 13, BlockRegistry.void_block_1, world);
		this.setBlock(i + 17, j + 5, k + 14, Blocks.quartz_block, world);
		this.setBlock(i + 17, j + 5, k + 15, ModFluids.rud_block, world);
		this.setBlock(i + 17, j + 5, k + 16, ModFluids.rud_block, world);
		this.setBlock(i + 17, j + 5, k + 17, Blocks.quartz_block, world);
		this.setBlock(i + 17, j + 5, k + 18, BlockRegistry.void_block_1, world);
		this.setBlock(i + 17, j + 6, k + 14, BlockRegistry.void_block_1, world);
		this.setBlock(i + 17, j + 6, k + 15, Blocks.sandstone_stairs, world);
		this.setBlock(i + 17, j + 6, k + 16, Blocks.sandstone_stairs, world);
		this.setBlock(i + 17, j + 6, k + 17, BlockRegistry.void_block_1, world);
		this.setBlock(i + 17, j + 29, k + 12, BlockRegistry.silver_ore_1, world);
		this.setBlock(i + 17, j + 29, k + 13, BlockRegistry.silver_ore_1, world);
		this.setBlock(i + 17, j + 29, k + 14, BlockRegistry.silver_ore_1, world);
		this.setBlock(i + 17, j + 29, k + 15, BlockRegistry.void_block_1, world);
		this.setBlock(i + 17, j + 29, k + 16, BlockRegistry.void_block_1, world);
		this.setBlock(i + 17, j + 29, k + 17, BlockRegistry.silver_ore_1, world);
		this.setBlock(i + 17, j + 29, k + 18, BlockRegistry.silver_ore_1, world);
		this.setBlock(i + 17, j + 29, k + 19, BlockRegistry.silver_ore_1, world);
		this.setBlock(i + 17, j + 30, k + 10, BlockRegistry.silver_ore_1, world);
		this.setBlock(i + 17, j + 30, k + 11, BlockRegistry.silver_ore_1, world);
		this.setBlock(i + 17, j + 30, k + 20, BlockRegistry.silver_ore_1, world);
		this.setBlock(i + 17, j + 30, k + 21, BlockRegistry.silver_ore_1, world);
		this.setBlock(i + 17, j + 31, k + 9, BlockRegistry.silver_ore_1, world);
		this.setBlock(i + 17, j + 31, k + 10, BlockRegistry.void_block_1, world);
		this.setBlock(i + 17, j + 31, k + 11, BlockRegistry.void_block_1, world);
		this.setBlock(i + 17, j + 31, k + 12, BlockRegistry.void_block_1, world);
		this.setBlock(i + 17, j + 31, k + 13, BlockRegistry.void_block_1, world);
		this.setBlock(i + 17, j + 31, k + 14, BlockRegistry.void_block_1, world);
		this.setBlock(i + 17, j + 31, k + 15, BlockRegistry.void_block_1, world);
		this.setBlock(i + 17, j + 31, k + 16, BlockRegistry.void_block_1, world);
		this.setBlock(i + 17, j + 31, k + 17, BlockRegistry.void_block_1, world);
		this.setBlock(i + 17, j + 31, k + 18, BlockRegistry.void_block_1, world);
		this.setBlock(i + 17, j + 31, k + 19, BlockRegistry.void_block_1, world);
		this.setBlock(i + 17, j + 31, k + 20, BlockRegistry.void_block_1, world);
		this.setBlock(i + 17, j + 31, k + 21, BlockRegistry.void_block_1, world);
		this.setBlock(i + 17, j + 31, k + 22, BlockRegistry.silver_ore_1, world);
		this.setBlock(i + 17, j + 32, k + 7, BlockRegistry.void_block_1, world);
		this.setBlock(i + 17, j + 32, k + 8, BlockRegistry.silver_ore_1, world);
		this.setBlock(i + 17, j + 32, k + 23, BlockRegistry.silver_ore_1, world);
		this.setBlock(i + 17, j + 32, k + 24, BlockRegistry.void_block_1, world);
		this.setBlock(i + 17, j + 33, k + 6, BlockRegistry.void_block_1, world);
		this.setBlock(i + 17, j + 33, k + 7, BlockRegistry.silver_ore_1, world);
		this.setBlock(i + 17, j + 33, k + 20, BlockRegistry.void_block_1, world);
		this.setBlock(i + 17, j + 33, k + 21, BlockRegistry.void_block_1, world);
		this.setBlock(i + 17, j + 33, k + 22, BlockRegistry.void_block_1, world);
		this.setBlock(i + 17, j + 33, k + 23, BlockRegistry.void_block_1, world);
		this.setBlock(i + 17, j + 33, k + 24, BlockRegistry.silver_ore_1, world);
		this.setBlock(i + 17, j + 33, k + 25, BlockRegistry.void_block_1, world);
		this.setBlock(i + 17, j + 34, k + 5, BlockRegistry.void_block_1, world);
		this.setBlock(i + 17, j + 34, k + 6, BlockRegistry.silver_ore_1, world);
		this.setBlock(i + 17, j + 34, k + 15, BlockRegistry.void_block_1, world);
		this.setBlock(i + 17, j + 34, k + 16, BlockRegistry.void_block_1, world);
		this.setBlock(i + 17, j + 34, k + 25, BlockRegistry.silver_ore_1, world);
		this.setBlock(i + 17, j + 34, k + 26, BlockRegistry.void_block_1, world);
		this.setBlock(i + 18, j + 0, k + 0, Blocks.snow, world);
		this.setBlock(i + 18, j + 0, k + 1, Blocks.snow, world);
		this.setBlock(i + 18, j + 0, k + 2, Blocks.snow, world);
		this.setBlock(i + 18, j + 0, k + 3, Blocks.snow, world);
		this.setBlock(i + 18, j + 0, k + 4, Blocks.snow, world);
		this.setBlock(i + 18, j + 0, k + 5, Blocks.snow, world);
		this.setBlock(i + 18, j + 0, k + 6, Blocks.snow, world);
		this.setBlock(i + 18, j + 0, k + 7, Blocks.snow, world);
		this.setBlock(i + 18, j + 0, k + 8, Blocks.snow, world);
		this.setBlock(i + 18, j + 0, k + 9, Blocks.snow, world);
		this.setBlock(i + 18, j + 0, k + 10, Blocks.snow, world);
		this.setBlock(i + 18, j + 0, k + 11, Blocks.snow, world);
		this.setBlock(i + 18, j + 0, k + 12, Blocks.snow, world);
		this.setBlock(i + 18, j + 0, k + 13, Blocks.quartz_block, world);
		this.setBlock(i + 18, j + 0, k + 14, Blocks.quartz_block, world);
		this.setBlock(i + 18, j + 0, k + 15, Blocks.quartz_block, world);
		this.setBlock(i + 18, j + 0, k + 16, Blocks.quartz_block, world);
		this.setBlock(i + 18, j + 0, k + 17, Blocks.quartz_block, world);
		this.setBlock(i + 18, j + 0, k + 18, Blocks.quartz_block, world);
		this.setBlock(i + 18, j + 0, k + 19, Blocks.quartz_block, world);
		this.setBlock(i + 18, j + 0, k + 20, Blocks.quartz_block, world);
		this.setBlock(i + 18, j + 0, k + 21, Blocks.quartz_block, world);
		this.setBlock(i + 18, j + 0, k + 22, Blocks.quartz_block, world);
		this.setBlock(i + 18, j + 0, k + 23, Blocks.quartz_block, world);
		this.setBlock(i + 18, j + 0, k + 24, Blocks.snow, world);
		this.setBlock(i + 18, j + 0, k + 25, Blocks.snow, world);
		this.setBlock(i + 18, j + 0, k + 26, Blocks.snow, world);
		this.setBlock(i + 18, j + 0, k + 27, Blocks.snow, world);
		this.setBlock(i + 18, j + 0, k + 28, Blocks.snow, world);
		this.setBlock(i + 18, j + 0, k + 29, Blocks.snow, world);
		this.setBlock(i + 18, j + 0, k + 30, Blocks.snow, world);
		this.setBlock(i + 18, j + 0, k + 31, Blocks.snow, world);
		this.setBlock(i + 18, j + 1, k + 8, BlockRegistry.void_block_1, world);
		this.setBlock(i + 18, j + 1, k + 9, Blocks.quartz_block, world);
		this.setBlock(i + 18, j + 1, k + 10, Blocks.quartz_block, world);
		this.setBlock(i + 18, j + 1, k + 11, Blocks.quartz_block, world);
		this.setBlock(i + 18, j + 1, k + 12, Blocks.quartz_block, world);
		this.setBlock(i + 18, j + 1, k + 13, Blocks.quartz_block, world);
		this.setBlock(i + 18, j + 1, k + 14, Blocks.quartz_block, world);
		this.setBlock(i + 18, j + 1, k + 15, Blocks.quartz_block, world);
		this.setBlock(i + 18, j + 1, k + 16, Blocks.quartz_block, world);
		this.setBlock(i + 18, j + 1, k + 17, Blocks.quartz_block, world);
		this.setBlock(i + 18, j + 1, k + 18, Blocks.quartz_block, world);
		this.setBlock(i + 18, j + 1, k + 19, Blocks.quartz_block, world);
		this.setBlock(i + 18, j + 1, k + 20, Blocks.quartz_block, world);
		this.setBlock(i + 18, j + 1, k + 21, Blocks.quartz_block, world);
		this.setBlock(i + 18, j + 1, k + 22, Blocks.quartz_block, world);
		this.setBlock(i + 18, j + 1, k + 23, BlockRegistry.void_block_1, world);
		this.setBlock(i + 18, j + 2, k + 9, BlockRegistry.void_block_1, world);
		this.setBlock(i + 18, j + 2, k + 10, Blocks.quartz_block, world);
		this.setBlock(i + 18, j + 2, k + 11, Blocks.quartz_block, world);
		this.setBlock(i + 18, j + 2, k + 12, Blocks.quartz_block, world);
		this.setBlock(i + 18, j + 2, k + 13, Blocks.quartz_block, world);
		this.setBlock(i + 18, j + 2, k + 14, Blocks.quartz_block, world);
		this.setBlock(i + 18, j + 2, k + 15, Blocks.quartz_block, world);
		this.setBlock(i + 18, j + 2, k + 16, Blocks.quartz_block, world);
		this.setBlock(i + 18, j + 2, k + 17, Blocks.quartz_block, world);
		this.setBlock(i + 18, j + 2, k + 18, Blocks.quartz_block, world);
		this.setBlock(i + 18, j + 2, k + 19, Blocks.quartz_block, world);
		this.setBlock(i + 18, j + 2, k + 20, Blocks.quartz_block, world);
		this.setBlock(i + 18, j + 2, k + 21, Blocks.quartz_block, world);
		this.setBlock(i + 18, j + 2, k + 22, BlockRegistry.void_block_1, world);
		this.setBlock(i + 18, j + 3, k + 10, BlockRegistry.void_block_1, world);
		this.setBlock(i + 18, j + 3, k + 11, Blocks.quartz_block, world);
		this.setBlock(i + 18, j + 3, k + 12, Blocks.quartz_block, world);
		this.setBlock(i + 18, j + 3, k + 13, Blocks.quartz_block, world);
		this.setBlock(i + 18, j + 3, k + 14, Blocks.quartz_block, world);
		this.setBlock(i + 18, j + 3, k + 15, Blocks.quartz_block, world);
		this.setBlock(i + 18, j + 3, k + 16, Blocks.quartz_block, world);
		this.setBlock(i + 18, j + 3, k + 17, Blocks.quartz_block, world);
		this.setBlock(i + 18, j + 3, k + 18, Blocks.quartz_block, world);
		this.setBlock(i + 18, j + 3, k + 19, Blocks.quartz_block, world);
		this.setBlock(i + 18, j + 3, k + 20, Blocks.quartz_block, world);
		this.setBlock(i + 18, j + 3, k + 21, BlockRegistry.void_block_1, world);
		this.setBlock(i + 18, j + 4, k + 11, BlockRegistry.void_block_1, world);
		this.setBlock(i + 18, j + 4, k + 12, Blocks.quartz_block, world);
		this.setBlock(i + 18, j + 4, k + 13, Blocks.quartz_block, world);
		this.setBlock(i + 18, j + 4, k + 14, Blocks.quartz_block, world);
		this.setBlock(i + 18, j + 4, k + 15, Blocks.quartz_block, world);
		this.setBlock(i + 18, j + 4, k + 16, Blocks.quartz_block, world);
		this.setBlock(i + 18, j + 4, k + 17, Blocks.quartz_block, world);
		this.setBlock(i + 18, j + 4, k + 18, Blocks.quartz_block, world);
		this.setBlock(i + 18, j + 4, k + 19, Blocks.quartz_block, world);
		this.setBlock(i + 18, j + 4, k + 20, BlockRegistry.void_block_1, world);
		this.setBlock(i + 18, j + 5, k + 12, BlockRegistry.void_block_1, world);
		this.setBlock(i + 18, j + 5, k + 13, Blocks.quartz_block, world);
		this.setBlock(i + 18, j + 5, k + 14, Blocks.quartz_block, world);
		this.setBlock(i + 18, j + 5, k + 15, Blocks.quartz_block, world);
		this.setBlock(i + 18, j + 5, k + 16, Blocks.quartz_block, world);
		this.setBlock(i + 18, j + 5, k + 17, Blocks.quartz_block, world);
		this.setBlock(i + 18, j + 5, k + 18, Blocks.quartz_block, world);
		this.setBlock(i + 18, j + 5, k + 19, BlockRegistry.void_block_1, world);
		this.setBlock(i + 18, j + 6, k + 13, BlockRegistry.void_block_1, world);
		this.setBlock(i + 18, j + 6, k + 14, Blocks.quartz_block, world);
		this.setBlock(i + 18, j + 6, k + 15, ModFluids.rud_block, world);
		this.setBlock(i + 18, j + 6, k + 16, ModFluids.rud_block, world);
		this.setBlock(i + 18, j + 6, k + 17, Blocks.quartz_block, world);
		this.setBlock(i + 18, j + 6, k + 18, BlockRegistry.void_block_1, world);
		this.setBlock(i + 18, j + 7, k + 14, BlockRegistry.void_block_1, world);
		this.setBlock(i + 18, j + 7, k + 15, Blocks.sandstone_stairs, world);
		this.setBlock(i + 18, j + 7, k + 16, Blocks.sandstone_stairs, world);
		this.setBlock(i + 18, j + 7, k + 17, BlockRegistry.void_block_1, world);
		this.setBlock(i + 18, j + 27, k + 13, BlockRegistry.silver_ore_1, world);
		this.setBlock(i + 18, j + 27, k + 14, BlockRegistry.silver_ore_1, world);
		this.setBlock(i + 18, j + 27, k + 15, BlockRegistry.void_block_1, world);
		this.setBlock(i + 18, j + 27, k + 16, BlockRegistry.void_block_1, world);
		this.setBlock(i + 18, j + 27, k + 17, BlockRegistry.silver_ore_1, world);
		this.setBlock(i + 18, j + 27, k + 18, BlockRegistry.silver_ore_1, world);
		this.setBlock(i + 18, j + 28, k + 12, BlockRegistry.silver_ore_1, world);
		this.setBlock(i + 18, j + 28, k + 13, BlockRegistry.silver_ore_1, world);
		this.setBlock(i + 18, j + 28, k + 14, BlockRegistry.silver_ore_1, world);
		this.setBlock(i + 18, j + 28, k + 15, BlockRegistry.void_block_1, world);
		this.setBlock(i + 18, j + 28, k + 16, BlockRegistry.void_block_1, world);
		this.setBlock(i + 18, j + 28, k + 17, BlockRegistry.silver_ore_1, world);
		this.setBlock(i + 18, j + 28, k + 18, BlockRegistry.silver_ore_1, world);
		this.setBlock(i + 18, j + 28, k + 19, BlockRegistry.silver_ore_1, world);
		this.setBlock(i + 18, j + 29, k + 11, BlockRegistry.silver_ore_1, world);
		this.setBlock(i + 18, j + 29, k + 12, BlockRegistry.silver_ore_1, world);
		this.setBlock(i + 18, j + 29, k + 13, BlockRegistry.silver_ore_1, world);
		this.setBlock(i + 18, j + 29, k + 14, BlockRegistry.silver_ore_1, world);
		this.setBlock(i + 18, j + 29, k + 15, BlockRegistry.silver_ore_1, world);
		this.setBlock(i + 18, j + 29, k + 16, BlockRegistry.silver_ore_1, world);
		this.setBlock(i + 18, j + 29, k + 17, BlockRegistry.silver_ore_1, world);
		this.setBlock(i + 18, j + 29, k + 18, BlockRegistry.silver_ore_1, world);
		this.setBlock(i + 18, j + 29, k + 19, BlockRegistry.silver_ore_1, world);
		this.setBlock(i + 18, j + 29, k + 20, BlockRegistry.silver_ore_1, world);
		this.setBlock(i + 18, j + 30, k + 10, BlockRegistry.void_block_1, world);
		this.setBlock(i + 18, j + 30, k + 17, Blocks.wool, world);
		this.setBlock(i + 18, j + 30, k + 21, BlockRegistry.void_block_1, world);
		this.setBlock(i + 18, j + 31, k + 9, BlockRegistry.void_block_1, world);
		this.setBlock(i + 18, j + 31, k + 10, BlockRegistry.void_block_1, world);
		this.setBlock(i + 18, j + 31, k + 11, BlockRegistry.void_block_1, world);
		this.setBlock(i + 18, j + 31, k + 12, BlockRegistry.void_block_1, world);
		this.setBlock(i + 18, j + 31, k + 13, BlockRegistry.void_block_1, world);
		this.setBlock(i + 18, j + 31, k + 15, BlockRegistry.void_block_1, world);
		this.setBlock(i + 18, j + 31, k + 16, BlockRegistry.void_block_1, world);
		this.setBlock(i + 18, j + 31, k + 17, Blocks.wool, world);
		this.setBlock(i + 18, j + 31, k + 18, BlockRegistry.void_block_1, world);
		this.setBlock(i + 18, j + 31, k + 19, BlockRegistry.void_block_1, world);
		this.setBlock(i + 18, j + 31, k + 20, BlockRegistry.void_block_1, world);
		this.setBlock(i + 18, j + 31, k + 21, BlockRegistry.void_block_1, world);
		this.setBlock(i + 18, j + 31, k + 22, BlockRegistry.void_block_1, world);
		this.setBlock(i + 18, j + 32, k + 7, BlockRegistry.silver_ore_1, world);
		this.setBlock(i + 18, j + 32, k + 8, BlockRegistry.void_block_1, world);
		this.setBlock(i + 18, j + 32, k + 14, Blocks.wool, world);
		this.setBlock(i + 18, j + 32, k + 17, Blocks.wool, world);
		this.setBlock(i + 18, j + 32, k + 23, BlockRegistry.void_block_1, world);
		this.setBlock(i + 18, j + 32, k + 24, BlockRegistry.silver_ore_1, world);
		this.setBlock(i + 18, j + 33, k + 5, BlockRegistry.void_block_1, world);
		this.setBlock(i + 18, j + 33, k + 6, BlockRegistry.silver_ore_1, world);
		this.setBlock(i + 18, j + 33, k + 14, Blocks.wool, world);
		this.setBlock(i + 18, j + 33, k + 17, Blocks.wool, world);
		this.setBlock(i + 18, j + 33, k + 20, BlockRegistry.void_block_1, world);
		this.setBlock(i + 18, j + 33, k + 21, BlockRegistry.void_block_1, world);
		this.setBlock(i + 18, j + 33, k + 22, BlockRegistry.void_block_1, world);
		this.setBlock(i + 18, j + 33, k + 23, BlockRegistry.void_block_1, world);
		this.setBlock(i + 18, j + 33, k + 24, BlockRegistry.void_block_1, world);
		this.setBlock(i + 18, j + 33, k + 25, BlockRegistry.silver_ore_1, world);
		this.setBlock(i + 18, j + 33, k + 26, BlockRegistry.void_block_1, world);
		this.setBlock(i + 18, j + 34, k + 4, BlockRegistry.void_block_1, world);
		this.setBlock(i + 18, j + 34, k + 5, BlockRegistry.silver_ore_1, world);
		this.setBlock(i + 18, j + 34, k + 6, BlockRegistry.void_block_1, world);
		this.setBlock(i + 18, j + 34, k + 14, Blocks.wool, world);
		this.setBlock(i + 18, j + 34, k + 15, BlockRegistry.void_block_1, world);
		this.setBlock(i + 18, j + 34, k + 16, BlockRegistry.void_block_1, world);
		this.setBlock(i + 18, j + 34, k + 17, Blocks.wool, world);
		this.setBlock(i + 18, j + 34, k + 25, BlockRegistry.void_block_1, world);
		this.setBlock(i + 18, j + 34, k + 26, BlockRegistry.silver_ore_1, world);
		this.setBlock(i + 18, j + 34, k + 27, BlockRegistry.void_block_1, world);
		this.setBlock(i + 19, j + 0, k + 0, Blocks.snow, world);
		this.setBlock(i + 19, j + 0, k + 1, Blocks.snow, world);
		this.setBlock(i + 19, j + 0, k + 2, Blocks.snow, world);
		this.setBlock(i + 19, j + 0, k + 3, Blocks.snow, world);
		this.setBlock(i + 19, j + 0, k + 4, Blocks.snow, world);
		this.setBlock(i + 19, j + 0, k + 5, Blocks.snow, world);
		this.setBlock(i + 19, j + 0, k + 6, Blocks.snow, world);
		this.setBlock(i + 19, j + 0, k + 7, Blocks.snow, world);
		this.setBlock(i + 19, j + 0, k + 8, Blocks.snow, world);
		this.setBlock(i + 19, j + 0, k + 9, Blocks.snow, world);
		this.setBlock(i + 19, j + 0, k + 10, Blocks.snow, world);
		this.setBlock(i + 19, j + 0, k + 11, Blocks.snow, world);
		this.setBlock(i + 19, j + 0, k + 12, Blocks.snow, world);
		this.setBlock(i + 19, j + 0, k + 13, Blocks.quartz_block, world);
		this.setBlock(i + 19, j + 0, k + 14, Blocks.quartz_block, world);
		this.setBlock(i + 19, j + 0, k + 15, Blocks.quartz_block, world);
		this.setBlock(i + 19, j + 0, k + 16, Blocks.quartz_block, world);
		this.setBlock(i + 19, j + 0, k + 17, Blocks.quartz_block, world);
		this.setBlock(i + 19, j + 0, k + 18, Blocks.quartz_block, world);
		this.setBlock(i + 19, j + 0, k + 19, Blocks.quartz_block, world);
		this.setBlock(i + 19, j + 0, k + 20, Blocks.quartz_block, world);
		this.setBlock(i + 19, j + 0, k + 21, Blocks.quartz_block, world);
		this.setBlock(i + 19, j + 0, k + 22, Blocks.quartz_block, world);
		this.setBlock(i + 19, j + 0, k + 23, Blocks.quartz_block, world);
		this.setBlock(i + 19, j + 0, k + 24, Blocks.quartz_block, world);
		this.setBlock(i + 19, j + 0, k + 26, Blocks.snow, world);
		this.setBlock(i + 19, j + 0, k + 27, Blocks.snow, world);
		this.setBlock(i + 19, j + 0, k + 28, Blocks.snow, world);
		this.setBlock(i + 19, j + 0, k + 29, Blocks.snow, world);
		this.setBlock(i + 19, j + 0, k + 30, Blocks.snow, world);
		this.setBlock(i + 19, j + 0, k + 31, Blocks.snow, world);
		this.setBlock(i + 19, j + 1, k + 7, BlockRegistry.void_block_1, world);
		this.setBlock(i + 19, j + 1, k + 8, Blocks.quartz_block, world);
		this.setBlock(i + 19, j + 1, k + 9, Blocks.quartz_block, world);
		this.setBlock(i + 19, j + 1, k + 10, Blocks.quartz_block, world);
		this.setBlock(i + 19, j + 1, k + 11, Blocks.quartz_block, world);
		this.setBlock(i + 19, j + 1, k + 12, Blocks.quartz_block, world);
		this.setBlock(i + 19, j + 1, k + 13, Blocks.quartz_block, world);
		this.setBlock(i + 19, j + 1, k + 14, Blocks.quartz_block, world);
		this.setBlock(i + 19, j + 1, k + 15, Blocks.quartz_block, world);
		this.setBlock(i + 19, j + 1, k + 16, Blocks.quartz_block, world);
		this.setBlock(i + 19, j + 1, k + 17, Blocks.quartz_block, world);
		this.setBlock(i + 19, j + 1, k + 18, Blocks.quartz_block, world);
		this.setBlock(i + 19, j + 1, k + 19, Blocks.quartz_block, world);
		this.setBlock(i + 19, j + 1, k + 20, Blocks.quartz_block, world);
		this.setBlock(i + 19, j + 1, k + 21, Blocks.quartz_block, world);
		this.setBlock(i + 19, j + 1, k + 22, Blocks.quartz_block, world);
		this.setBlock(i + 19, j + 1, k + 23, Blocks.quartz_block, world);
		this.setBlock(i + 19, j + 1, k + 24, BlockRegistry.void_block_1, world);
		this.setBlock(i + 19, j + 2, k + 8, BlockRegistry.void_block_1, world);
		this.setBlock(i + 19, j + 2, k + 9, Blocks.quartz_block, world);
		this.setBlock(i + 19, j + 2, k + 10, Blocks.quartz_block, world);
		this.setBlock(i + 19, j + 2, k + 11, Blocks.quartz_block, world);
		this.setBlock(i + 19, j + 2, k + 12, Blocks.quartz_block, world);
		this.setBlock(i + 19, j + 2, k + 13, Blocks.quartz_block, world);
		this.setBlock(i + 19, j + 2, k + 14, Blocks.quartz_block, world);
		this.setBlock(i + 19, j + 2, k + 15, Blocks.quartz_block, world);
		this.setBlock(i + 19, j + 2, k + 16, Blocks.quartz_block, world);
		this.setBlock(i + 19, j + 2, k + 17, Blocks.quartz_block, world);
		this.setBlock(i + 19, j + 2, k + 18, Blocks.quartz_block, world);
		this.setBlock(i + 19, j + 2, k + 19, Blocks.quartz_block, world);
		this.setBlock(i + 19, j + 2, k + 20, Blocks.quartz_block, world);
		this.setBlock(i + 19, j + 2, k + 21, Blocks.quartz_block, world);
		this.setBlock(i + 19, j + 2, k + 22, Blocks.quartz_block, world);
		this.setBlock(i + 19, j + 2, k + 23, BlockRegistry.void_block_1, world);
		this.setBlock(i + 19, j + 3, k + 9, BlockRegistry.void_block_1, world);
		this.setBlock(i + 19, j + 3, k + 10, Blocks.quartz_block, world);
		this.setBlock(i + 19, j + 3, k + 11, Blocks.quartz_block, world);
		this.setBlock(i + 19, j + 3, k + 12, Blocks.quartz_block, world);
		this.setBlock(i + 19, j + 3, k + 13, Blocks.quartz_block, world);
		this.setBlock(i + 19, j + 3, k + 14, Blocks.quartz_block, world);
		this.setBlock(i + 19, j + 3, k + 15, Blocks.quartz_block, world);
		this.setBlock(i + 19, j + 3, k + 16, Blocks.quartz_block, world);
		this.setBlock(i + 19, j + 3, k + 17, Blocks.quartz_block, world);
		this.setBlock(i + 19, j + 3, k + 18, Blocks.quartz_block, world);
		this.setBlock(i + 19, j + 3, k + 19, Blocks.quartz_block, world);
		this.setBlock(i + 19, j + 3, k + 20, Blocks.quartz_block, world);
		this.setBlock(i + 19, j + 3, k + 21, Blocks.quartz_block, world);
		this.setBlock(i + 19, j + 3, k + 22, BlockRegistry.void_block_1, world);
		this.setBlock(i + 19, j + 4, k + 10, BlockRegistry.void_block_1, world);
		this.setBlock(i + 19, j + 4, k + 11, Blocks.quartz_block, world);
		this.setBlock(i + 19, j + 4, k + 12, Blocks.quartz_block, world);
		this.setBlock(i + 19, j + 4, k + 13, Blocks.quartz_block, world);
		this.setBlock(i + 19, j + 4, k + 14, Blocks.quartz_block, world);
		this.setBlock(i + 19, j + 4, k + 15, Blocks.quartz_block, world);
		this.setBlock(i + 19, j + 4, k + 16, Blocks.quartz_block, world);
		this.setBlock(i + 19, j + 4, k + 17, Blocks.quartz_block, world);
		this.setBlock(i + 19, j + 4, k + 18, Blocks.quartz_block, world);
		this.setBlock(i + 19, j + 4, k + 19, Blocks.quartz_block, world);
		this.setBlock(i + 19, j + 4, k + 20, Blocks.quartz_block, world);
		this.setBlock(i + 19, j + 4, k + 21, BlockRegistry.void_block_1, world);
		this.setBlock(i + 19, j + 5, k + 11, BlockRegistry.void_block_1, world);
		this.setBlock(i + 19, j + 5, k + 12, Blocks.quartz_block, world);
		this.setBlock(i + 19, j + 5, k + 13, Blocks.quartz_block, world);
		this.setBlock(i + 19, j + 5, k + 14, Blocks.quartz_block, world);
		this.setBlock(i + 19, j + 5, k + 15, Blocks.quartz_block, world);
		this.setBlock(i + 19, j + 5, k + 16, Blocks.quartz_block, world);
		this.setBlock(i + 19, j + 5, k + 17, Blocks.quartz_block, world);
		this.setBlock(i + 19, j + 5, k + 18, Blocks.quartz_block, world);
		this.setBlock(i + 19, j + 5, k + 19, Blocks.quartz_block, world);
		this.setBlock(i + 19, j + 5, k + 20, BlockRegistry.void_block_1, world);
		this.setBlock(i + 19, j + 6, k + 12, BlockRegistry.void_block_1, world);
		this.setBlock(i + 19, j + 6, k + 13, Blocks.quartz_block, world);
		this.setBlock(i + 19, j + 6, k + 14, Blocks.quartz_block, world);
		this.setBlock(i + 19, j + 6, k + 15, Blocks.quartz_block, world);
		this.setBlock(i + 19, j + 6, k + 16, Blocks.quartz_block, world);
		this.setBlock(i + 19, j + 6, k + 17, Blocks.quartz_block, world);
		this.setBlock(i + 19, j + 6, k + 18, Blocks.quartz_block, world);
		this.setBlock(i + 19, j + 6, k + 19, BlockRegistry.void_block_1, world);
		this.setBlock(i + 19, j + 7, k + 13, BlockRegistry.void_block_1, world);
		this.setBlock(i + 19, j + 7, k + 14, Blocks.quartz_block, world);
		this.setBlock(i + 19, j + 7, k + 15, ModFluids.rud_block, world);
		this.setBlock(i + 19, j + 7, k + 16, ModFluids.rud_block, world);
		this.setBlock(i + 19, j + 7, k + 17, Blocks.quartz_block, world);
		this.setBlock(i + 19, j + 7, k + 18, BlockRegistry.void_block_1, world);
		this.setBlock(i + 19, j + 8, k + 14, BlockRegistry.void_block_1, world);
		this.setBlock(i + 19, j + 8, k + 15, Blocks.sandstone_stairs, world);
		this.setBlock(i + 19, j + 8, k + 16, Blocks.sandstone_stairs, world);
		this.setBlock(i + 19, j + 8, k + 17, BlockRegistry.void_block_1, world);
		this.setBlock(i + 19, j + 25, k + 14, BlockRegistry.silver_ore_1, world);
		this.setBlock(i + 19, j + 25, k + 15, BlockRegistry.void_block_1, world);
		this.setBlock(i + 19, j + 25, k + 16, BlockRegistry.void_block_1, world);
		this.setBlock(i + 19, j + 25, k + 17, BlockRegistry.silver_ore_1, world);
		this.setBlock(i + 19, j + 26, k + 13, BlockRegistry.silver_ore_1, world);
		this.setBlock(i + 19, j + 26, k + 14, BlockRegistry.silver_ore_1, world);
		this.setBlock(i + 19, j + 26, k + 15, BlockRegistry.void_block_1, world);
		this.setBlock(i + 19, j + 26, k + 16, BlockRegistry.void_block_1, world);
		this.setBlock(i + 19, j + 26, k + 17, BlockRegistry.silver_ore_1, world);
		this.setBlock(i + 19, j + 26, k + 18, BlockRegistry.silver_ore_1, world);
		this.setBlock(i + 19, j + 27, k + 12, BlockRegistry.silver_ore_1, world);
		this.setBlock(i + 19, j + 27, k + 13, BlockRegistry.silver_ore_1, world);
		this.setBlock(i + 19, j + 27, k + 14, BlockRegistry.silver_ore_1, world);
		this.setBlock(i + 19, j + 27, k + 15, BlockRegistry.void_block_1, world);
		this.setBlock(i + 19, j + 27, k + 16, BlockRegistry.void_block_1, world);
		this.setBlock(i + 19, j + 27, k + 17, BlockRegistry.silver_ore_1, world);
		this.setBlock(i + 19, j + 27, k + 18, BlockRegistry.silver_ore_1, world);
		this.setBlock(i + 19, j + 27, k + 19, BlockRegistry.silver_ore_1, world);
		this.setBlock(i + 19, j + 28, k + 12, BlockRegistry.silver_ore_1, world);
		this.setBlock(i + 19, j + 28, k + 13, BlockRegistry.silver_ore_1, world);
		this.setBlock(i + 19, j + 28, k + 14, BlockRegistry.silver_ore_1, world);
		this.setBlock(i + 19, j + 28, k + 15, BlockRegistry.void_block_1, world);
		this.setBlock(i + 19, j + 28, k + 16, BlockRegistry.void_block_1, world);
		this.setBlock(i + 19, j + 28, k + 17, BlockRegistry.silver_ore_1, world);
		this.setBlock(i + 19, j + 28, k + 18, BlockRegistry.silver_ore_1, world);
		this.setBlock(i + 19, j + 28, k + 19, BlockRegistry.silver_ore_1, world);
		this.setBlock(i + 19, j + 29, k + 11, BlockRegistry.silver_ore_1, world);
		this.setBlock(i + 19, j + 29, k + 12, BlockRegistry.silver_ore_1, world);
		this.setBlock(i + 19, j + 29, k + 13, BlockRegistry.silver_ore_1, world);
		this.setBlock(i + 19, j + 29, k + 14, BlockRegistry.silver_ore_1, world);
		this.setBlock(i + 19, j + 29, k + 15, BlockRegistry.void_block_1, world);
		this.setBlock(i + 19, j + 29, k + 16, BlockRegistry.void_block_1, world);
		this.setBlock(i + 19, j + 29, k + 17, BlockRegistry.silver_ore_1, world);
		this.setBlock(i + 19, j + 29, k + 18, BlockRegistry.silver_ore_1, world);
		this.setBlock(i + 19, j + 29, k + 19, BlockRegistry.silver_ore_1, world);
		this.setBlock(i + 19, j + 29, k + 20, BlockRegistry.silver_ore_1, world);
		this.setBlock(i + 19, j + 30, k + 10, BlockRegistry.void_block_1, world);
		this.setBlock(i + 19, j + 30, k + 15, BlockRegistry.void_block_1, world);
		this.setBlock(i + 19, j + 30, k + 16, BlockRegistry.void_block_1, world);
		this.setBlock(i + 19, j + 30, k + 17, Blocks.wool, world);
		this.setBlock(i + 19, j + 30, k + 18, Blocks.wool, world);
		this.setBlock(i + 19, j + 30, k + 21, BlockRegistry.void_block_1, world);
		this.setBlock(i + 19, j + 31, k + 9, BlockRegistry.void_block_1, world);
		this.setBlock(i + 19, j + 31, k + 10, BlockRegistry.void_block_1, world);
		this.setBlock(i + 19, j + 31, k + 11, BlockRegistry.void_block_1, world);
		this.setBlock(i + 19, j + 31, k + 12, BlockRegistry.void_block_1, world);
		this.setBlock(i + 19, j + 31, k + 15, BlockRegistry.void_block_1, world);
		this.setBlock(i + 19, j + 31, k + 16, BlockRegistry.void_block_1, world);
		this.setBlock(i + 19, j + 31, k + 17, Blocks.wool, world);
		this.setBlock(i + 19, j + 31, k + 18, Blocks.wool, world);
		this.setBlock(i + 19, j + 31, k + 19, BlockRegistry.void_block_1, world);
		this.setBlock(i + 19, j + 31, k + 20, BlockRegistry.void_block_1, world);
		this.setBlock(i + 19, j + 31, k + 21, BlockRegistry.void_block_1, world);
		this.setBlock(i + 19, j + 31, k + 22, BlockRegistry.void_block_1, world);
		this.setBlock(i + 19, j + 32, k + 7, BlockRegistry.void_block_1, world);
		this.setBlock(i + 19, j + 32, k + 8, BlockRegistry.void_block_1, world);
		this.setBlock(i + 19, j + 32, k + 13, Blocks.wool, world);
		this.setBlock(i + 19, j + 32, k + 14, Blocks.wool, world);
		this.setBlock(i + 19, j + 32, k + 15, BlockRegistry.void_block_1, world);
		this.setBlock(i + 19, j + 32, k + 16, BlockRegistry.void_block_1, world);
		this.setBlock(i + 19, j + 32, k + 17, Blocks.wool, world);
		this.setBlock(i + 19, j + 32, k + 18, Blocks.wool, world);
		this.setBlock(i + 19, j + 32, k + 23, BlockRegistry.void_block_1, world);
		this.setBlock(i + 19, j + 32, k + 24, BlockRegistry.void_block_1, world);
		this.setBlock(i + 19, j + 33, k + 4, BlockRegistry.void_block_1, world);
		this.setBlock(i + 19, j + 33, k + 5, BlockRegistry.silver_ore_1, world);
		this.setBlock(i + 19, j + 33, k + 6, BlockRegistry.void_block_1, world);
		this.setBlock(i + 19, j + 33, k + 13, Blocks.wool, world);
		this.setBlock(i + 19, j + 33, k + 14, Blocks.wool, world);
		this.setBlock(i + 19, j + 33, k + 15, BlockRegistry.void_block_1, world);
		this.setBlock(i + 19, j + 33, k + 16, BlockRegistry.void_block_1, world);
		this.setBlock(i + 19, j + 33, k + 17, Blocks.wool, world);
		this.setBlock(i + 19, j + 33, k + 18, Blocks.wool, world);
		this.setBlock(i + 19, j + 33, k + 20, BlockRegistry.void_block_1, world);
		this.setBlock(i + 19, j + 33, k + 21, BlockRegistry.void_block_1, world);
		this.setBlock(i + 19, j + 33, k + 22, BlockRegistry.void_block_1, world);
		this.setBlock(i + 19, j + 33, k + 23, BlockRegistry.void_block_1, world);
		this.setBlock(i + 19, j + 33, k + 24, BlockRegistry.void_block_1, world);
		this.setBlock(i + 19, j + 33, k + 25, BlockRegistry.void_block_1, world);
		this.setBlock(i + 19, j + 33, k + 26, BlockRegistry.silver_ore_1, world);
		this.setBlock(i + 19, j + 33, k + 27, BlockRegistry.void_block_1, world);
		this.setBlock(i + 19, j + 34, k + 3, BlockRegistry.void_block_1, world);
		this.setBlock(i + 19, j + 34, k + 4, BlockRegistry.silver_ore_1, world);
		this.setBlock(i + 19, j + 34, k + 5, BlockRegistry.void_block_1, world);
		this.setBlock(i + 19, j + 34, k + 6, BlockRegistry.void_block_1, world);
		this.setBlock(i + 19, j + 34, k + 13, Blocks.wool, world);
		this.setBlock(i + 19, j + 34, k + 14, Blocks.wool, world);
		this.setBlock(i + 19, j + 34, k + 15, BlockRegistry.void_block_1, world);
		this.setBlock(i + 19, j + 34, k + 16, BlockRegistry.void_block_1, world);
		this.setBlock(i + 19, j + 34, k + 17, Blocks.wool, world);
		this.setBlock(i + 19, j + 34, k + 18, Blocks.wool, world);
		this.setBlock(i + 19, j + 34, k + 25, BlockRegistry.void_block_1, world);
		this.setBlock(i + 19, j + 34, k + 26, BlockRegistry.void_block_1, world);
		this.setBlock(i + 19, j + 34, k + 27, BlockRegistry.silver_ore_1, world);
		this.setBlock(i + 19, j + 34, k + 28, BlockRegistry.void_block_1, world);
		this.setBlock(i + 20, j + 0, k + 0, Blocks.snow, world);
		this.setBlock(i + 20, j + 0, k + 1, Blocks.snow, world);
		this.setBlock(i + 20, j + 0, k + 2, Blocks.snow, world);
		this.setBlock(i + 20, j + 0, k + 3, Blocks.snow, world);
		this.setBlock(i + 20, j + 0, k + 4, Blocks.snow, world);
		this.setBlock(i + 20, j + 0, k + 5, Blocks.snow, world);
		this.setBlock(i + 20, j + 0, k + 6, Blocks.snow, world);
		this.setBlock(i + 20, j + 0, k + 7, Blocks.snow, world);
		this.setBlock(i + 20, j + 0, k + 8, Blocks.snow, world);
		this.setBlock(i + 20, j + 0, k + 9, Blocks.snow, world);
		this.setBlock(i + 20, j + 0, k + 10, Blocks.snow, world);
		this.setBlock(i + 20, j + 0, k + 11, Blocks.snow, world);
		this.setBlock(i + 20, j + 0, k + 12, Blocks.snow, world);
		this.setBlock(i + 20, j + 0, k + 13, Blocks.quartz_block, world);
		this.setBlock(i + 20, j + 0, k + 14, Blocks.quartz_block, world);
		this.setBlock(i + 20, j + 0, k + 15, Blocks.quartz_block, world);
		this.setBlock(i + 20, j + 0, k + 16, Blocks.quartz_block, world);
		this.setBlock(i + 20, j + 0, k + 17, Blocks.quartz_block, world);
		this.setBlock(i + 20, j + 0, k + 18, Blocks.quartz_block, world);
		this.setBlock(i + 20, j + 0, k + 19, Blocks.quartz_block, world);
		this.setBlock(i + 20, j + 0, k + 20, Blocks.quartz_block, world);
		this.setBlock(i + 20, j + 0, k + 21, Blocks.quartz_block, world);
		this.setBlock(i + 20, j + 0, k + 22, Blocks.quartz_block, world);
		this.setBlock(i + 20, j + 0, k + 23, Blocks.quartz_block, world);
		this.setBlock(i + 20, j + 0, k + 24, Blocks.quartz_block, world);
		this.setBlock(i + 20, j + 0, k + 26, Blocks.snow, world);
		this.setBlock(i + 20, j + 0, k + 27, Blocks.snow, world);
		this.setBlock(i + 20, j + 0, k + 28, Blocks.snow, world);
		this.setBlock(i + 20, j + 0, k + 29, Blocks.snow, world);
		this.setBlock(i + 20, j + 0, k + 30, Blocks.snow, world);
		this.setBlock(i + 20, j + 0, k + 31, Blocks.snow, world);
		this.setBlock(i + 20, j + 1, k + 6, BlockRegistry.void_block_1, world);
		this.setBlock(i + 20, j + 1, k + 7, Blocks.quartz_block, world);
		this.setBlock(i + 20, j + 1, k + 8, Blocks.quartz_block, world);
		this.setBlock(i + 20, j + 1, k + 9, Blocks.quartz_block, world);
		this.setBlock(i + 20, j + 1, k + 10, Blocks.quartz_block, world);
		this.setBlock(i + 20, j + 1, k + 11, Blocks.quartz_block, world);
